Workbook

Sheet Dashboard
A1: ⚡ FiscalFlow Financial Intelligence & Budget Command Center
A3: Real-time automated analytics based on your Sigma Soft Tech Park master budget (₹31,000) and bank statement ingestion.
A5: TOTAL MONTHLY INFLOW | D5: TOTAL EXPENSES & ALLOCATIONS | G5: WEALTH & EMERGENCY ASSETS | J5: NET CASH SURPLUS / BUFFER
A6: ='Budget vs Actual'!D9 | D6: ='Budget vs Actual'!D20 | G6: ='Budget vs Actual'!D17+'Budget vs Actual'!D18 | J6: ='Budget vs Actual'!D9-'Budget vs Actual'!D20
A7: ='Budget vs Actual'!G9 & ' (Target: ₹' & TEXT('Master Budget'!C9,'#,##0') & ')' | D7: ='Budget vs Actual'!G20 & ' (Burn: ' & TEXT('Budget vs Actual'!E20,'0.0%') & ')' | G7: ='SIP: ₹' & TEXT('Budget vs Actual'!D18,'#,##0') & ' | Emergency: ₹' & TEXT('Budget vs Actual'!D17,'#,##0') | J7: ='Unallocated Buffer Left: ₹' & TEXT('Budget vs Actual'!F19,'#,##0')
A9: 📊 CATEGORY BUDGET HEALTH & OVERGROWN DETECTION SUMMARY
A10: Category Line Item | B10: Planned (₹) | C10: Actual (₹) | D10: Burn % | E10: Remaining / Over (₹) | F10: Status Alert
A11: ='Budget vs Actual'!A13 | B11: ='Budget vs Actual'!C13 | C11: ='Budget vs Actual'!D13 | D11: ='Budget vs Actual'!E13 | E11: ='Budget vs Actual'!F13 | F11: ='Budget vs Actual'!G13
A12: ='Budget vs Actual'!A14 | B12: ='Budget vs Actual'!C14 | C12: ='Budget vs Actual'!D14 | D12: ='Budget vs Actual'!E14 | E12: ='Budget vs Actual'!F14 | F12: ='Budget vs Actual'!G14
A13: ='Budget vs Actual'!A15 | B13: ='Budget vs Actual'!C15 | C13: ='Budget vs Actual'!D15 | D13: ='Budget vs Actual'!E15 | E13: ='Budget vs Actual'!F15 | F13: ='Budget vs Actual'!G15
A14: ='Budget vs Actual'!A16 | B14: ='Budget vs Actual'!C16 | C14: ='Budget vs Actual'!D16 | D14: ='Budget vs Actual'!E16 | E14: ='Budget vs Actual'!F16 | F14: ='Budget vs Actual'!G16
A15: ='Budget vs Actual'!A17 | B15: ='Budget vs Actual'!C17 | C15: ='Budget vs Actual'!D17 | D15: ='Budget vs Actual'!E17 | E15: ='Budget vs Actual'!F17 | F15: ='Budget vs Actual'!G17
A16: ='Budget vs Actual'!A18 | B16: ='Budget vs Actual'!C18 | C16: ='Budget vs Actual'!D18 | D16: ='Budget vs Actual'!E18 | E16: ='Budget vs Actual'!F18 | F16: ='Budget vs Actual'!G18
A17: ='Budget vs Actual'!A19 | B17: ='Budget vs Actual'!C19 | C17: ='Budget vs Actual'!D19 | D17: ='Budget vs Actual'!E19 | E17: ='Budget vs Actual'!F19 | F17: ='Budget vs Actual'!G19
A20: 📈 VISUAL COMPARISON: PLANNED BUDGET VS ACTUAL SPEND
H21: 💡 HOW TO USE THIS AUTOMATED TRACKER
H23: Step 1 | I23: Paste your bank statement in 'Bank Statements' sheet under columns A:G (Tran Date, CHQNO, PARTICULARS, DR, CR, BAL, SOL).
H24: Step 2 | I24: Columns H:M automatically detect transaction type, match keywords, and categorize your transactions instantly.
H25: Step 3 | I25: If a transaction needs manual adjustment, simply select or type the category in Column J ('Override Category').
H26: Step 4 | I26: Check 'Budget vs Actual' to see real-time over-budget warnings, burn rate %, and cash buffer balance.
H27: Step 5 | I27: To modify your income, PG rent, SIP, or buffer limits, edit the values in 'Master Budget'. All formulas update automatically!

Sheet Master Budget
A1: 🎯 Master Financial Budget & Allocation Model
A3: 💡 Note: Edit amounts in Column C. Formulas automatically update percentages, totals, variance checks, and dashboard charts.
A5: 1. MONTHLY INCOME SOURCES
A6: Category / Line Item | B6: Type | C6: Monthly Amount (₹) | D6: % of Total Funds | E6: Target Cap (₹) | F6: Notes & Strategy
A7: Internship Stipend | B7: Income | C7: 25000 | D7: =C7/$C$9 | E7: 25000 | F7: Primary monthly earning from Sigma Soft Tech Park internship.
A8: Family Support | B8: Income | C8: 6000 | D8: =C8/$C$9 | E8: 6000 | F8: Supplementary monthly family contribution.
A9: Total Monthly Cash Flow | B9: Total Inflow | C9: =SUM(C7:C8) | D9: =C9/C9 | E9: =SUM(E7:E8) | F9: Combined available liquid funds.
A11: 2. PLANNED MONTHLY ALLOCATIONS & EXPENSES (Budget Distribution)
A12: Category / Line Item | B12: Type | C12: Monthly Amount (₹) | D12: % of Total Funds | E12: Target Cap (₹) | F12: Notes & Strategy
A13: PG Rent & Covered Meals | B13: Living Expense | C13: 14000 | D13: =C13/$C$9 | E13: 14000 | F13: Breakfast & dinner daily, Saturday full meals, Sunday breakfast.
A14: Daily Office Lunch (Mon–Sat) | B14: Food & Dining | C14: 3250 | D14: =C14/$C$9 | E14: 3500 | F14: 26 working days @ ₹100–150/day in/near Sigma Soft Tech Park.
A15: BMTC Bus Commute | B15: Transport | C15: 1000 | D15: =C15/$C$9 | E15: 1200 | F15: Daily bus fares between Varthur Kodi and Kundalahalli Gate.
A16: Lifestyle & Personal Essentials | B16: Personal & Bills | C16: 3500 | D16: =C16/$C$9 | E16: 4000 | F16: Sunday meals, mobile recharge, toiletries, laundry supplies.
A17: Emergency Fund Allocation | B17: Savings Reserve | C17: 2750 | D17: =C17/$C$9 | E17: 3000 | F17: Built up monthly in liquid bank savings for safety buffer.
A18: Monthly SIP Investment | B18: Wealth Creation | C18: 5500 | D18: =C18/$C$9 | E18: 5500 | F18: Capped fixed wealth-building auto-investment in Mutual Funds.
A19: Unallocated Flex Buffer | B19: Cash Buffer | C19: 1000 | D19: =C19/$C$9 | E19: 1000 | F19: Extra cash left untouched in your bank account for unexpected needs.
A20: Total Planned Monthly Allocations | B20: Total Outflow | C20: =SUM(C13:C19) | D20: =C20/$C$9 | E20: =SUM(E13:E19) | F20: 100% Budget allocation aligned with income.
A22: Zero-Based Budget Balance Check: | C22: =C9-C20 | D22: =IF(C22=0, "✅ Perfectly Balanced (₹0 Unassigned)", "⚠️ Unbalanced Allocation")

Sheet Category Rules
A1: ⚙️ Auto-Categorization Rules & Keyword Matching Engine
A3: This dictionary drives automated sorting of your statement particulars. You can add more keywords anytime!
A5: Master Category | B5: Type | C5: Keywords (Comma Separated) | D5: Priority | E5: Example Merchants / Narrations
A6: Internship Stipend | B6: Income | C6: STIPEND, SIGMA, SIGMASOFT, SALARY, PAYROLL, TECH PARK | D6: High | E6: SIGMA TECH PARK STIPEND OCT, NEFT-SIGMASOFT
A7: Family Support | B7: Income | C7: FAMILY, PAPA, MOM, FATHER, MOTHER, PARENT, HOME | D7: High | E7: UPI-FATHER TRANSFER, IMPS-MOM-SUPPORT
A8: PG Rent & Covered Meals | B8: Expense | C8: PG, RENT, LANDLORD, STAY, ZOLO, STANZA, ROOM, HOSTEL, ACCOMMODATION | D8: High | E8: UPI-PG-OWNER-RENT, ZOLO STAY NOV RENT
A9: Daily Office Lunch (Mon–Sat) | B9: Expense | C9: SWIGGY, ZOMATO, CANTEEN, CAFETERIA, CHAI, EATS, LUNCH, FOOD, MCDONALD, KFC, DOMINOS, SUBWAY, TACO, RESTAURANT, DHABA, MESS, BIRYANI | D9: Medium | E9: UPI-SWIGGY-BANGALORE, SIGMA FOOD COURT, CHAI POINT
A10: BMTC Bus Commute | B10: Expense | C10: BMTC, BUS, TICKET, NCMC, CHALO, METRO, BMRCL, CONDUCTOR, PASS, KUNDALAHALLI, VARTHUR | D10: High | E10: BMTC BUS PASS V-GATE, UPI-BMTC-TICKETING
A11: Lifestyle & Personal Essentials | B11: Expense | C11: AMAZON, FLIPKART, BLINKIT, ZEPTO, INSTAMART, RECHARGE, JIO, AIRTEL, VI, PHARMACY, APOLLO, 1MG, MEDPLUS, SUPERMARKET, DMART, LAUNDRY, SALON, BARBER | D11: Medium | E11: UPI-BLINKIT-GROCERY, JIO PREPAID RECHARGE, APOLLO PHARMACY
A12: Monthly SIP Investment | B12: Investment | C12: GROWW, ZERODHA, KITE, MUTUAL, MF, SIP, NIPPON, HDFC MF, UTI, PARAG, COIN, INDMONEY, CAMSONLINE, BSE, NSE, CDSL | D12: High | E12: ACH-GROWW-SIP, BSE-MUTUAL-FUND-AUTO, ZERODHA BROKING
A13: Emergency Fund Allocation | B13: Savings | C13: EMERGENCY, AUTO SWEEP, FD, FIXED DEP, RESERVE, SAVINGS XFER, LIQUID FUND | D13: Medium | E13: SWEEP TO LIQUID SAVINGS, FD CREATION
A14: Unallocated Flex Buffer | B14: Buffer | C14: ATM, CASH, MISC, BUFFER, CONTINGENCY | D14: Low | E14: ATM CASH WITHDRAWAL, MISC LOCAL UPI

Sheet Bank Statements
A1: 📑 Bank Statement Ingestion & Automated Transaction Ledger
A3: 📋 Instructions: Paste your bank statement in columns A to G. Columns H to M automatically categorize, detect transaction type, and flag budget impacts!
A5: Tran Date | B5: CHQNO | C5: PARTICULARS | D5: DR | E5: CR | F5: BAL | G5: SOL | H5: Txn Type | I5: Auto Category | J5: Override Category (Optional) | K5: Final Category | L5: Month | M5: Spend Warning / Tag
A6: 01-10-2026 | B6: SAL982104 | C6: NEFT CR-SIGMA SOFT TECH PARK-STIPEND FOR OCT | E6: 25000 | F6: 28500 | G6: BLR01 | H6: =IF(C6="","",IF(E6>0,"INCOME",IF(D6>0,"EXPENSE","NEUTRAL"))) | I6: =IF(C6="","",=IF(OR(ISNUMBER(SEARCH("STIPEND",C6)),ISNUMBER(SEARCH("SIGMASOFT",C6)),ISNUMBER(SEARCH("SALARY",C6))),"Internship Stipend",IF(OR(ISNUMBER(SEARCH("FAMILY",C6)),ISNUMBER(SEARCH("PAPA",C6)),ISNUMBER(SEARCH("MOM",C6)),ISNUMBER(SEARCH("FATHER",C6))),"Family Support",IF(OR(ISNUMBER(SEARCH("PG",C6)),ISNUMBER(SEARCH("RENT",C6)),ISNUMBER(SEARCH("STANZA",C6)),ISNUMBER(SEARCH("ZOLO",C6))),"PG Rent & Covered Meals",IF(OR(ISNUMBER(SEARCH("GROWW",C6)),ISNUMBER(SEARCH("ZERODHA",C6)),ISNUMBER(SEARCH("MUTUAL",C6)),ISNUMBER(SEARCH("SIP",C6)),ISNUMBER(SEARCH("NIPPON",C6))),"Monthly SIP Investment",IF(OR(ISNUMBER(SEARCH("BMTC",C6)),ISNUMBER(SEARCH("BUS",C6)),ISNUMBER(SEARCH("METRO",C6)),ISNUMBER(SEARCH("CHALO",C6))),"BMTC Bus Commute",IF(OR(ISNUMBER(SEARCH("SWIGGY",C6)),ISNUMBER(SEARCH("ZOMATO",C6)),ISNUMBER(SEARCH("CANTEEN",C6)),ISNUMBER(SEARCH("LUNCH",C6)),ISNUMBER(SEARCH("FOOD",C6)),ISNUMBER(SEARCH("SUBWAY",C6))),"Daily Office Lunch (Mon–Sat)",IF(OR(ISNUMBER(SEARCH("BLINKIT",C6)),ISNUMBER(SEARCH("ZEPTO",C6)),ISNUMBER(SEARCH("RECHARGE",C6)),ISNUMBER(SEARCH("JIO",C6)),ISNUMBER(SEARCH("AIRTEL",C6)),ISNUMBER(SEARCH("PHARMACY",C6)),ISNUMBER(SEARCH("APOLLO",C6)),ISNUMBER(SEARCH("ESSENTIALS",C6)),ISNUMBER(SEARCH("LIFESTYLE",C6))),"Lifestyle & Personal Essentials",IF(OR(ISNUMBER(SEARCH("EMERGENCY",C6)),ISNUMBER(SEARCH("SWEEP",C6)),ISNUMBER(SEARCH("RESERVE",C6))),"Emergency Fund Allocation","Unallocated Flex Buffer"))))))))) | K6: =IF(C6="","",IF(J6<>"",J6,I6)) | L6: =IF(A6="","",IF(ISNUMBER(A6),TEXT(A6,"mmm-yyyy"),"Oct-2026")) | M6: =IF(D6>=5000,"🚨 High Value Debit (₹"&TEXT(D6,"#,##0")&")",IF(D6>=1000,"⚡ Notable Expense","—"))
A7: 02-10-2026 | B7: UPI481023 | C7: UPI/PAPA/FAMILY MONTHLY SUPPORT/SBIN0029 | E7: 6000 | F7: 34500 | G7: DEL04 | H7: =IF(C7="","",IF(E7>0,"INCOME",IF(D7>0,"EXPENSE","NEUTRAL"))) | I7: =IF(C7="","",=IF(OR(ISNUMBER(SEARCH("STIPEND",C7)),ISNUMBER(SEARCH("SIGMASOFT",C7)),ISNUMBER(SEARCH("SALARY",C7))),"Internship Stipend",IF(OR(ISNUMBER(SEARCH("FAMILY",C7)),ISNUMBER(SEARCH("PAPA",C7)),ISNUMBER(SEARCH("MOM",C7)),ISNUMBER(SEARCH("FATHER",C7))),"Family Support",IF(OR(ISNUMBER(SEARCH("PG",C7)),ISNUMBER(SEARCH("RENT",C7)),ISNUMBER(SEARCH("STANZA",C7)),ISNUMBER(SEARCH("ZOLO",C7))),"PG Rent & Covered Meals",IF(OR(ISNUMBER(SEARCH("GROWW",C7)),ISNUMBER(SEARCH("ZERODHA",C7)),ISNUMBER(SEARCH("MUTUAL",C7)),ISNUMBER(SEARCH("SIP",C7)),ISNUMBER(SEARCH("NIPPON",C7))),"Monthly SIP Investment",IF(OR(ISNUMBER(SEARCH("BMTC",C7)),ISNUMBER(SEARCH("BUS",C7)),ISNUMBER(SEARCH("METRO",C7)),ISNUMBER(SEARCH("CHALO",C7))),"BMTC Bus Commute",IF(OR(ISNUMBER(SEARCH("SWIGGY",C7)),ISNUMBER(SEARCH("ZOMATO",C7)),ISNUMBER(SEARCH("CANTEEN",C7)),ISNUMBER(SEARCH("LUNCH",C7)),ISNUMBER(SEARCH("FOOD",C7)),ISNUMBER(SEARCH("SUBWAY",C7))),"Daily Office Lunch (Mon–Sat)",IF(OR(ISNUMBER(SEARCH("BLINKIT",C7)),ISNUMBER(SEARCH("ZEPTO",C7)),ISNUMBER(SEARCH("RECHARGE",C7)),ISNUMBER(SEARCH("JIO",C7)),ISNUMBER(SEARCH("AIRTEL",C7)),ISNUMBER(SEARCH("PHARMACY",C7)),ISNUMBER(SEARCH("APOLLO",C7)),ISNUMBER(SEARCH("ESSENTIALS",C7)),ISNUMBER(SEARCH("LIFESTYLE",C7))),"Lifestyle & Personal Essentials",IF(OR(ISNUMBER(SEARCH("EMERGENCY",C7)),ISNUMBER(SEARCH("SWEEP",C7)),ISNUMBER(SEARCH("RESERVE",C7))),"Emergency Fund Allocation","Unallocated Flex Buffer"))))))))) | K7: =IF(C7="","",IF(J7<>"",J7,I7)) | L7: =IF(A7="","",IF(ISNUMBER(A7),TEXT(A7,"mmm-yyyy"),"Oct-2026")) | M7: =IF(D7>=5000,"🚨 High Value Debit (₹"&TEXT(D7,"#,##0")&")",IF(D7>=1000,"⚡ Notable Expense","—"))
A8: 02-10-2026 | B8: CHQ000182 | C8: CHQ PAID-STANZA LIVING PG RENT & MEALS OCT | D8: 14000 | F8: 20500 | G8: BLR01 | H8: =IF(C8="","",IF(E8>0,"INCOME",IF(D8>0,"EXPENSE","NEUTRAL"))) | I8: =IF(C8="","",=IF(OR(ISNUMBER(SEARCH("STIPEND",C8)),ISNUMBER(SEARCH("SIGMASOFT",C8)),ISNUMBER(SEARCH("SALARY",C8))),"Internship Stipend",IF(OR(ISNUMBER(SEARCH("FAMILY",C8)),ISNUMBER(SEARCH("PAPA",C8)),ISNUMBER(SEARCH("MOM",C8)),ISNUMBER(SEARCH("FATHER",C8))),"Family Support",IF(OR(ISNUMBER(SEARCH("PG",C8)),ISNUMBER(SEARCH("RENT",C8)),ISNUMBER(SEARCH("STANZA",C8)),ISNUMBER(SEARCH("ZOLO",C8))),"PG Rent & Covered Meals",IF(OR(ISNUMBER(SEARCH("GROWW",C8)),ISNUMBER(SEARCH("ZERODHA",C8)),ISNUMBER(SEARCH("MUTUAL",C8)),ISNUMBER(SEARCH("SIP",C8)),ISNUMBER(SEARCH("NIPPON",C8))),"Monthly SIP Investment",IF(OR(ISNUMBER(SEARCH("BMTC",C8)),ISNUMBER(SEARCH("BUS",C8)),ISNUMBER(SEARCH("METRO",C8)),ISNUMBER(SEARCH("CHALO",C8))),"BMTC Bus Commute",IF(OR(ISNUMBER(SEARCH("SWIGGY",C8)),ISNUMBER(SEARCH("ZOMATO",C8)),ISNUMBER(SEARCH("CANTEEN",C8)),ISNUMBER(SEARCH("LUNCH",C8)),ISNUMBER(SEARCH("FOOD",C8)),ISNUMBER(SEARCH("SUBWAY",C8))),"Daily Office Lunch (Mon–Sat)",IF(OR(ISNUMBER(SEARCH("BLINKIT",C8)),ISNUMBER(SEARCH("ZEPTO",C8)),ISNUMBER(SEARCH("RECHARGE",C8)),ISNUMBER(SEARCH("JIO",C8)),ISNUMBER(SEARCH("AIRTEL",C8)),ISNUMBER(SEARCH("PHARMACY",C8)),ISNUMBER(SEARCH("APOLLO",C8)),ISNUMBER(SEARCH("ESSENTIALS",C8)),ISNUMBER(SEARCH("LIFESTYLE",C8))),"Lifestyle & Personal Essentials",IF(OR(ISNUMBER(SEARCH("EMERGENCY",C8)),ISNUMBER(SEARCH("SWEEP",C8)),ISNUMBER(SEARCH("RESERVE",C8))),"Emergency Fund Allocation","Unallocated Flex Buffer"))))))))) | K8: =IF(C8="","",IF(J8<>"",J8,I8)) | L8: =IF(A8="","",IF(ISNUMBER(A8),TEXT(A8,"mmm-yyyy"),"Oct-2026")) | M8: =IF(D8>=5000,"🚨 High Value Debit (₹"&TEXT(D8,"#,##0")&")",IF(D8>=1000,"⚡ Notable Expense","—"))
A9: 03-10-2026 | B9: ACH891204 | C9: ACH DR-GROWW MUTUAL FUND NIPPON SMALL CAP SIP | D9: 3000 | F9: 17500 | G9: MUM02 | H9: =IF(C9="","",IF(E9>0,"INCOME",IF(D9>0,"EXPENSE","NEUTRAL"))) | I9: =IF(C9="","",=IF(OR(ISNUMBER(SEARCH("STIPEND",C9)),ISNUMBER(SEARCH("SIGMASOFT",C9)),ISNUMBER(SEARCH("SALARY",C9))),"Internship Stipend",IF(OR(ISNUMBER(SEARCH("FAMILY",C9)),ISNUMBER(SEARCH("PAPA",C9)),ISNUMBER(SEARCH("MOM",C9)),ISNUMBER(SEARCH("FATHER",C9))),"Family Support",IF(OR(ISNUMBER(SEARCH("PG",C9)),ISNUMBER(SEARCH("RENT",C9)),ISNUMBER(SEARCH("STANZA",C9)),ISNUMBER(SEARCH("ZOLO",C9))),"PG Rent & Covered Meals",IF(OR(ISNUMBER(SEARCH("GROWW",C9)),ISNUMBER(SEARCH("ZERODHA",C9)),ISNUMBER(SEARCH("MUTUAL",C9)),ISNUMBER(SEARCH("SIP",C9)),ISNUMBER(SEARCH("NIPPON",C9))),"Monthly SIP Investment",IF(OR(ISNUMBER(SEARCH("BMTC",C9)),ISNUMBER(SEARCH("BUS",C9)),ISNUMBER(SEARCH("METRO",C9)),ISNUMBER(SEARCH("CHALO",C9))),"BMTC Bus Commute",IF(OR(ISNUMBER(SEARCH("SWIGGY",C9)),ISNUMBER(SEARCH("ZOMATO",C9)),ISNUMBER(SEARCH("CANTEEN",C9)),ISNUMBER(SEARCH("LUNCH",C9)),ISNUMBER(SEARCH("FOOD",C9)),ISNUMBER(SEARCH("SUBWAY",C9))),"Daily Office Lunch (Mon–Sat)",IF(OR(ISNUMBER(SEARCH("BLINKIT",C9)),ISNUMBER(SEARCH("ZEPTO",C9)),ISNUMBER(SEARCH("RECHARGE",C9)),ISNUMBER(SEARCH("JIO",C9)),ISNUMBER(SEARCH("AIRTEL",C9)),ISNUMBER(SEARCH("PHARMACY",C9)),ISNUMBER(SEARCH("APOLLO",C9)),ISNUMBER(SEARCH("ESSENTIALS",C9)),ISNUMBER(SEARCH("LIFESTYLE",C9))),"Lifestyle & Personal Essentials",IF(OR(ISNUMBER(SEARCH("EMERGENCY",C9)),ISNUMBER(SEARCH("SWEEP",C9)),ISNUMBER(SEARCH("RESERVE",C9))),"Emergency Fund Allocation","Unallocated Flex Buffer"))))))))) | K9: =IF(C9="","",IF(J9<>"",J9,I9)) | L9: =IF(A9="","",IF(ISNUMBER(A9),TEXT(A9,"mmm-yyyy"),"Oct-2026")) | M9: =IF(D9>=5000,"🚨 High Value Debit (₹"&TEXT(D9,"#,##0")&")",IF(D9>=1000,"⚡ Notable Expense","—"))
A10: 03-10-2026 | B10: ACH891205 | C10: ACH DR-ZERODHA PARAG PARIKH FLEXI CAP SIP | D10: 2500 | F10: 15000 | G10: MUM02 | H10: =IF(C10="","",IF(E10>0,"INCOME",IF(D10>0,"EXPENSE","NEUTRAL"))) | I10: =IF(C10="","",=IF(OR(ISNUMBER(SEARCH("STIPEND",C10)),ISNUMBER(SEARCH("SIGMASOFT",C10)),ISNUMBER(SEARCH("SALARY",C10))),"Internship Stipend",IF(OR(ISNUMBER(SEARCH("FAMILY",C10)),ISNUMBER(SEARCH("PAPA",C10)),ISNUMBER(SEARCH("MOM",C10)),ISNUMBER(SEARCH("FATHER",C10))),"Family Support",IF(OR(ISNUMBER(SEARCH("PG",C10)),ISNUMBER(SEARCH("RENT",C10)),ISNUMBER(SEARCH("STANZA",C10)),ISNUMBER(SEARCH("ZOLO",C10))),"PG Rent & Covered Meals",IF(OR(ISNUMBER(SEARCH("GROWW",C10)),ISNUMBER(SEARCH("ZERODHA",C10)),ISNUMBER(SEARCH("MUTUAL",C10)),ISNUMBER(SEARCH("SIP",C10)),ISNUMBER(SEARCH("NIPPON",C10))),"Monthly SIP Investment",IF(OR(ISNUMBER(SEARCH("BMTC",C10)),ISNUMBER(SEARCH("BUS",C10)),ISNUMBER(SEARCH("METRO",C10)),ISNUMBER(SEARCH("CHALO",C10))),"BMTC Bus Commute",IF(OR(ISNUMBER(SEARCH("SWIGGY",C10)),ISNUMBER(SEARCH("ZOMATO",C10)),ISNUMBER(SEARCH("CANTEEN",C10)),ISNUMBER(SEARCH("LUNCH",C10)),ISNUMBER(SEARCH("FOOD",C10)),ISNUMBER(SEARCH("SUBWAY",C10))),"Daily Office Lunch (Mon–Sat)",IF(OR(ISNUMBER(SEARCH("BLINKIT",C10)),ISNUMBER(SEARCH("ZEPTO",C10)),ISNUMBER(SEARCH("RECHARGE",C10)),ISNUMBER(SEARCH("JIO",C10)),ISNUMBER(SEARCH("AIRTEL",C10)),ISNUMBER(SEARCH("PHARMACY",C10)),ISNUMBER(SEARCH("APOLLO",C10)),ISNUMBER(SEARCH("ESSENTIALS",C10)),ISNUMBER(SEARCH("LIFESTYLE",C10))),"Lifestyle & Personal Essentials",IF(OR(ISNUMBER(SEARCH("EMERGENCY",C10)),ISNUMBER(SEARCH("SWEEP",C10)),ISNUMBER(SEARCH("RESERVE",C10))),"Emergency Fund Allocation","Unallocated Flex Buffer"))))))))) | K10: =IF(C10="","",IF(J10<>"",J10,I10)) | L10: =IF(A10="","",IF(ISNUMBER(A10),TEXT(A10,"mmm-yyyy"),"Oct-2026")) | M10: =IF(D10>=5000,"🚨 High Value Debit (₹"&TEXT(D10,"#,##0")&")",IF(D10>=1000,"⚡ Notable Expense","—"))
A11: 04-10-2026 | B11: UPI992101 | C11: UPI-BMTC BUS PASS MONTHLY KUNDALAHALLI GATE | D11: 1000 | F11: 14000 | G11: BLR02 | H11: =IF(C11="","",IF(E11>0,"INCOME",IF(D11>0,"EXPENSE","NEUTRAL"))) | I11: =IF(C11="","",=IF(OR(ISNUMBER(SEARCH("STIPEND",C11)),ISNUMBER(SEARCH("SIGMASOFT",C11)),ISNUMBER(SEARCH("SALARY",C11))),"Internship Stipend",IF(OR(ISNUMBER(SEARCH("FAMILY",C11)),ISNUMBER(SEARCH("PAPA",C11)),ISNUMBER(SEARCH("MOM",C11)),ISNUMBER(SEARCH("FATHER",C11))),"Family Support",IF(OR(ISNUMBER(SEARCH("PG",C11)),ISNUMBER(SEARCH("RENT",C11)),ISNUMBER(SEARCH("STANZA",C11)),ISNUMBER(SEARCH("ZOLO",C11))),"PG Rent & Covered Meals",IF(OR(ISNUMBER(SEARCH("GROWW",C11)),ISNUMBER(SEARCH("ZERODHA",C11)),ISNUMBER(SEARCH("MUTUAL",C11)),ISNUMBER(SEARCH("SIP",C11)),ISNUMBER(SEARCH("NIPPON",C11))),"Monthly SIP Investment",IF(OR(ISNUMBER(SEARCH("BMTC",C11)),ISNUMBER(SEARCH("BUS",C11)),ISNUMBER(SEARCH("METRO",C11)),ISNUMBER(SEARCH("CHALO",C11))),"BMTC Bus Commute",IF(OR(ISNUMBER(SEARCH("SWIGGY",C11)),ISNUMBER(SEARCH("ZOMATO",C11)),ISNUMBER(SEARCH("CANTEEN",C11)),ISNUMBER(SEARCH("LUNCH",C11)),ISNUMBER(SEARCH("FOOD",C11)),ISNUMBER(SEARCH("SUBWAY",C11))),"Daily Office Lunch (Mon–Sat)",IF(OR(ISNUMBER(SEARCH("BLINKIT",C11)),ISNUMBER(SEARCH("ZEPTO",C11)),ISNUMBER(SEARCH("RECHARGE",C11)),ISNUMBER(SEARCH("JIO",C11)),ISNUMBER(SEARCH("AIRTEL",C11)),ISNUMBER(SEARCH("PHARMACY",C11)),ISNUMBER(SEARCH("APOLLO",C11)),ISNUMBER(SEARCH("ESSENTIALS",C11)),ISNUMBER(SEARCH("LIFESTYLE",C11))),"Lifestyle & Personal Essentials",IF(OR(ISNUMBER(SEARCH("EMERGENCY",C11)),ISNUMBER(SEARCH("SWEEP",C11)),ISNUMBER(SEARCH("RESERVE",C11))),"Emergency Fund Allocation","Unallocated Flex Buffer"))))))))) | K11: =IF(C11="","",IF(J11<>"",J11,I11)) | L11: =IF(A11="","",IF(ISNUMBER(A11),TEXT(A11,"mmm-yyyy"),"Oct-2026")) | M11: =IF(D11>=5000,"🚨 High Value Debit (₹"&TEXT(D11,"#,##0")&")",IF(D11>=1000,"⚡ Notable Expense","—"))
A12: 05-10-2026 | B12: TXN102938 | C12: AUTO SWEEP TRANSFER TO LIQUID EMERGENCY FUND | D12: 2750 | F12: 11250 | G12: BLR01 | H12: =IF(C12="","",IF(E12>0,"INCOME",IF(D12>0,"EXPENSE","NEUTRAL"))) | I12: =IF(C12="","",=IF(OR(ISNUMBER(SEARCH("STIPEND",C12)),ISNUMBER(SEARCH("SIGMASOFT",C12)),ISNUMBER(SEARCH("SALARY",C12))),"Internship Stipend",IF(OR(ISNUMBER(SEARCH("FAMILY",C12)),ISNUMBER(SEARCH("PAPA",C12)),ISNUMBER(SEARCH("MOM",C12)),ISNUMBER(SEARCH("FATHER",C12))),"Family Support",IF(OR(ISNUMBER(SEARCH("PG",C12)),ISNUMBER(SEARCH("RENT",C12)),ISNUMBER(SEARCH("STANZA",C12)),ISNUMBER(SEARCH("ZOLO",C12))),"PG Rent & Covered Meals",IF(OR(ISNUMBER(SEARCH("GROWW",C12)),ISNUMBER(SEARCH("ZERODHA",C12)),ISNUMBER(SEARCH("MUTUAL",C12)),ISNUMBER(SEARCH("SIP",C12)),ISNUMBER(SEARCH("NIPPON",C12))),"Monthly SIP Investment",IF(OR(ISNUMBER(SEARCH("BMTC",C12)),ISNUMBER(SEARCH("BUS",C12)),ISNUMBER(SEARCH("METRO",C12)),ISNUMBER(SEARCH("CHALO",C12))),"BMTC Bus Commute",IF(OR(ISNUMBER(SEARCH("SWIGGY",C12)),ISNUMBER(SEARCH("ZOMATO",C12)),ISNUMBER(SEARCH("CANTEEN",C12)),ISNUMBER(SEARCH("LUNCH",C12)),ISNUMBER(SEARCH("FOOD",C12)),ISNUMBER(SEARCH("SUBWAY",C12))),"Daily Office Lunch (Mon–Sat)",IF(OR(ISNUMBER(SEARCH("BLINKIT",C12)),ISNUMBER(SEARCH("ZEPTO",C12)),ISNUMBER(SEARCH("RECHARGE",C12)),ISNUMBER(SEARCH("JIO",C12)),ISNUMBER(SEARCH("AIRTEL",C12)),ISNUMBER(SEARCH("PHARMACY",C12)),ISNUMBER(SEARCH("APOLLO",C12)),ISNUMBER(SEARCH("ESSENTIALS",C12)),ISNUMBER(SEARCH("LIFESTYLE",C12))),"Lifestyle & Personal Essentials",IF(OR(ISNUMBER(SEARCH("EMERGENCY",C12)),ISNUMBER(SEARCH("SWEEP",C12)),ISNUMBER(SEARCH("RESERVE",C12))),"Emergency Fund Allocation","Unallocated Flex Buffer"))))))))) | K12: =IF(C12="","",IF(J12<>"",J12,I12)) | L12: =IF(A12="","",IF(ISNUMBER(A12),TEXT(A12,"mmm-yyyy"),"Oct-2026")) | M12: =IF(D12>=5000,"🚨 High Value Debit (₹"&TEXT(D12,"#,##0")&")",IF(D12>=1000,"⚡ Notable Expense","—"))
A13: 06-10-2026 | B13: UPI392019 | C13: UPI-SIGMA FOOD COURT CANTEEN LUNCH THALI | D13: 130 | F13: 11120 | G13: BLR01 | H13: =IF(C13="","",IF(E13>0,"INCOME",IF(D13>0,"EXPENSE","NEUTRAL"))) | I13: =IF(C13="","",=IF(OR(ISNUMBER(SEARCH("STIPEND",C13)),ISNUMBER(SEARCH("SIGMASOFT",C13)),ISNUMBER(SEARCH("SALARY",C13))),"Internship Stipend",IF(OR(ISNUMBER(SEARCH("FAMILY",C13)),ISNUMBER(SEARCH("PAPA",C13)),ISNUMBER(SEARCH("MOM",C13)),ISNUMBER(SEARCH("FATHER",C13))),"Family Support",IF(OR(ISNUMBER(SEARCH("PG",C13)),ISNUMBER(SEARCH("RENT",C13)),ISNUMBER(SEARCH("STANZA",C13)),ISNUMBER(SEARCH("ZOLO",C13))),"PG Rent & Covered Meals",IF(OR(ISNUMBER(SEARCH("GROWW",C13)),ISNUMBER(SEARCH("ZERODHA",C13)),ISNUMBER(SEARCH("MUTUAL",C13)),ISNUMBER(SEARCH("SIP",C13)),ISNUMBER(SEARCH("NIPPON",C13))),"Monthly SIP Investment",IF(OR(ISNUMBER(SEARCH("BMTC",C13)),ISNUMBER(SEARCH("BUS",C13)),ISNUMBER(SEARCH("METRO",C13)),ISNUMBER(SEARCH("CHALO",C13))),"BMTC Bus Commute",IF(OR(ISNUMBER(SEARCH("SWIGGY",C13)),ISNUMBER(SEARCH("ZOMATO",C13)),ISNUMBER(SEARCH("CANTEEN",C13)),ISNUMBER(SEARCH("LUNCH",C13)),ISNUMBER(SEARCH("FOOD",C13)),ISNUMBER(SEARCH("SUBWAY",C13))),"Daily Office Lunch (Mon–Sat)",IF(OR(ISNUMBER(SEARCH("BLINKIT",C13)),ISNUMBER(SEARCH("ZEPTO",C13)),ISNUMBER(SEARCH("RECHARGE",C13)),ISNUMBER(SEARCH("JIO",C13)),ISNUMBER(SEARCH("AIRTEL",C13)),ISNUMBER(SEARCH("PHARMACY",C13)),ISNUMBER(SEARCH("APOLLO",C13)),ISNUMBER(SEARCH("ESSENTIALS",C13)),ISNUMBER(SEARCH("LIFESTYLE",C13))),"Lifestyle & Personal Essentials",IF(OR(ISNUMBER(SEARCH("EMERGENCY",C13)),ISNUMBER(SEARCH("SWEEP",C13)),ISNUMBER(SEARCH("RESERVE",C13))),"Emergency Fund Allocation","Unallocated Flex Buffer"))))))))) | K13: =IF(C13="","",IF(J13<>"",J13,I13)) | L13: =IF(A13="","",IF(ISNUMBER(A13),TEXT(A13,"mmm-yyyy"),"Oct-2026")) | M13: =IF(D13>=5000,"🚨 High Value Debit (₹"&TEXT(D13,"#,##0")&")",IF(D13>=1000,"⚡ Notable Expense","—"))
A14: 07-10-2026 | B14: UPI392020 | C14: UPI-SWIGGY MEALS SIGMA TECH PARK LUNCH | D14: 145 | F14: 10975 | G14: BLR01 | H14: =IF(C14="","",IF(E14>0,"INCOME",IF(D14>0,"EXPENSE","NEUTRAL"))) | I14: =IF(C14="","",=IF(OR(ISNUMBER(SEARCH("STIPEND",C14)),ISNUMBER(SEARCH("SIGMASOFT",C14)),ISNUMBER(SEARCH("SALARY",C14))),"Internship Stipend",IF(OR(ISNUMBER(SEARCH("FAMILY",C14)),ISNUMBER(SEARCH("PAPA",C14)),ISNUMBER(SEARCH("MOM",C14)),ISNUMBER(SEARCH("FATHER",C14))),"Family Support",IF(OR(ISNUMBER(SEARCH("PG",C14)),ISNUMBER(SEARCH("RENT",C14)),ISNUMBER(SEARCH("STANZA",C14)),ISNUMBER(SEARCH("ZOLO",C14))),"PG Rent & Covered Meals",IF(OR(ISNUMBER(SEARCH("GROWW",C14)),ISNUMBER(SEARCH("ZERODHA",C14)),ISNUMBER(SEARCH("MUTUAL",C14)),ISNUMBER(SEARCH("SIP",C14)),ISNUMBER(SEARCH("NIPPON",C14))),"Monthly SIP Investment",IF(OR(ISNUMBER(SEARCH("BMTC",C14)),ISNUMBER(SEARCH("BUS",C14)),ISNUMBER(SEARCH("METRO",C14)),ISNUMBER(SEARCH("CHALO",C14))),"BMTC Bus Commute",IF(OR(ISNUMBER(SEARCH("SWIGGY",C14)),ISNUMBER(SEARCH("ZOMATO",C14)),ISNUMBER(SEARCH("CANTEEN",C14)),ISNUMBER(SEARCH("LUNCH",C14)),ISNUMBER(SEARCH("FOOD",C14)),ISNUMBER(SEARCH("SUBWAY",C14))),"Daily Office Lunch (Mon–Sat)",IF(OR(ISNUMBER(SEARCH("BLINKIT",C14)),ISNUMBER(SEARCH("ZEPTO",C14)),ISNUMBER(SEARCH("RECHARGE",C14)),ISNUMBER(SEARCH("JIO",C14)),ISNUMBER(SEARCH("AIRTEL",C14)),ISNUMBER(SEARCH("PHARMACY",C14)),ISNUMBER(SEARCH("APOLLO",C14)),ISNUMBER(SEARCH("ESSENTIALS",C14)),ISNUMBER(SEARCH("LIFESTYLE",C14))),"Lifestyle & Personal Essentials",IF(OR(ISNUMBER(SEARCH("EMERGENCY",C14)),ISNUMBER(SEARCH("SWEEP",C14)),ISNUMBER(SEARCH("RESERVE",C14))),"Emergency Fund Allocation","Unallocated Flex Buffer"))))))))) | K14: =IF(C14="","",IF(J14<>"",J14,I14)) | L14: =IF(A14="","",IF(ISNUMBER(A14),TEXT(A14,"mmm-yyyy"),"Oct-2026")) | M14: =IF(D14>=5000,"🚨 High Value Debit (₹"&TEXT(D14,"#,##0")&")",IF(D14>=1000,"⚡ Notable Expense","—"))
A15: 08-10-2026 | B15: UPI392021 | C15: UPI-SIGMA TECH PARK NORTH INDIAN LUNCH | D15: 120 | F15: 10855 | G15: BLR01 | H15: =IF(C15="","",IF(E15>0,"INCOME",IF(D15>0,"EXPENSE","NEUTRAL"))) | I15: =IF(C15="","",=IF(OR(ISNUMBER(SEARCH("STIPEND",C15)),ISNUMBER(SEARCH("SIGMASOFT",C15)),ISNUMBER(SEARCH("SALARY",C15))),"Internship Stipend",IF(OR(ISNUMBER(SEARCH("FAMILY",C15)),ISNUMBER(SEARCH("PAPA",C15)),ISNUMBER(SEARCH("MOM",C15)),ISNUMBER(SEARCH("FATHER",C15))),"Family Support",IF(OR(ISNUMBER(SEARCH("PG",C15)),ISNUMBER(SEARCH("RENT",C15)),ISNUMBER(SEARCH("STANZA",C15)),ISNUMBER(SEARCH("ZOLO",C15))),"PG Rent & Covered Meals",IF(OR(ISNUMBER(SEARCH("GROWW",C15)),ISNUMBER(SEARCH("ZERODHA",C15)),ISNUMBER(SEARCH("MUTUAL",C15)),ISNUMBER(SEARCH("SIP",C15)),ISNUMBER(SEARCH("NIPPON",C15))),"Monthly SIP Investment",IF(OR(ISNUMBER(SEARCH("BMTC",C15)),ISNUMBER(SEARCH("BUS",C15)),ISNUMBER(SEARCH("METRO",C15)),ISNUMBER(SEARCH("CHALO",C15))),"BMTC Bus Commute",IF(OR(ISNUMBER(SEARCH("SWIGGY",C15)),ISNUMBER(SEARCH("ZOMATO",C15)),ISNUMBER(SEARCH("CANTEEN",C15)),ISNUMBER(SEARCH("LUNCH",C15)),ISNUMBER(SEARCH("FOOD",C15)),ISNUMBER(SEARCH("SUBWAY",C15))),"Daily Office Lunch (Mon–Sat)",IF(OR(ISNUMBER(SEARCH("BLINKIT",C15)),ISNUMBER(SEARCH("ZEPTO",C15)),ISNUMBER(SEARCH("RECHARGE",C15)),ISNUMBER(SEARCH("JIO",C15)),ISNUMBER(SEARCH("AIRTEL",C15)),ISNUMBER(SEARCH("PHARMACY",C15)),ISNUMBER(SEARCH("APOLLO",C15)),ISNUMBER(SEARCH("ESSENTIALS",C15)),ISNUMBER(SEARCH("LIFESTYLE",C15))),"Lifestyle & Personal Essentials",IF(OR(ISNUMBER(SEARCH("EMERGENCY",C15)),ISNUMBER(SEARCH("SWEEP",C15)),ISNUMBER(SEARCH("RESERVE",C15))),"Emergency Fund Allocation","Unallocated Flex Buffer"))))))))) | K15: =IF(C15="","",IF(J15<>"",J15,I15)) | L15: =IF(A15="","",IF(ISNUMBER(A15),TEXT(A15,"mmm-yyyy"),"Oct-2026")) | M15: =IF(D15>=5000,"🚨 High Value Debit (₹"&TEXT(D15,"#,##0")&")",IF(D15>=1000,"⚡ Notable Expense","—"))
A16: 09-10-2026 | B16: UPI392022 | C16: UPI-SUBWAY LUNCH SIGMA FOOD COURT | D16: 150 | F16: 10705 | G16: BLR01 | H16: =IF(C16="","",IF(E16>0,"INCOME",IF(D16>0,"EXPENSE","NEUTRAL"))) | I16: =IF(C16="","",=IF(OR(ISNUMBER(SEARCH("STIPEND",C16)),ISNUMBER(SEARCH("SIGMASOFT",C16)),ISNUMBER(SEARCH("SALARY",C16))),"Internship Stipend",IF(OR(ISNUMBER(SEARCH("FAMILY",C16)),ISNUMBER(SEARCH("PAPA",C16)),ISNUMBER(SEARCH("MOM",C16)),ISNUMBER(SEARCH("FATHER",C16))),"Family Support",IF(OR(ISNUMBER(SEARCH("PG",C16)),ISNUMBER(SEARCH("RENT",C16)),ISNUMBER(SEARCH("STANZA",C16)),ISNUMBER(SEARCH("ZOLO",C16))),"PG Rent & Covered Meals",IF(OR(ISNUMBER(SEARCH("GROWW",C16)),ISNUMBER(SEARCH("ZERODHA",C16)),ISNUMBER(SEARCH("MUTUAL",C16)),ISNUMBER(SEARCH("SIP",C16)),ISNUMBER(SEARCH("NIPPON",C16))),"Monthly SIP Investment",IF(OR(ISNUMBER(SEARCH("BMTC",C16)),ISNUMBER(SEARCH("BUS",C16)),ISNUMBER(SEARCH("METRO",C16)),ISNUMBER(SEARCH("CHALO",C16))),"BMTC Bus Commute",IF(OR(ISNUMBER(SEARCH("SWIGGY",C16)),ISNUMBER(SEARCH("ZOMATO",C16)),ISNUMBER(SEARCH("CANTEEN",C16)),ISNUMBER(SEARCH("LUNCH",C16)),ISNUMBER(SEARCH("FOOD",C16)),ISNUMBER(SEARCH("SUBWAY",C16))),"Daily Office Lunch (Mon–Sat)",IF(OR(ISNUMBER(SEARCH("BLINKIT",C16)),ISNUMBER(SEARCH("ZEPTO",C16)),ISNUMBER(SEARCH("RECHARGE",C16)),ISNUMBER(SEARCH("JIO",C16)),ISNUMBER(SEARCH("AIRTEL",C16)),ISNUMBER(SEARCH("PHARMACY",C16)),ISNUMBER(SEARCH("APOLLO",C16)),ISNUMBER(SEARCH("ESSENTIALS",C16)),ISNUMBER(SEARCH("LIFESTYLE",C16))),"Lifestyle & Personal Essentials",IF(OR(ISNUMBER(SEARCH("EMERGENCY",C16)),ISNUMBER(SEARCH("SWEEP",C16)),ISNUMBER(SEARCH("RESERVE",C16))),"Emergency Fund Allocation","Unallocated Flex Buffer"))))))))) | K16: =IF(C16="","",IF(J16<>"",J16,I16)) | L16: =IF(A16="","",IF(ISNUMBER(A16),TEXT(A16,"mmm-yyyy"),"Oct-2026")) | M16: =IF(D16>=5000,"🚨 High Value Debit (₹"&TEXT(D16,"#,##0")&")",IF(D16>=1000,"⚡ Notable Expense","—"))
A17: 10-10-2026 | B17: UPI440291 | C17: UPI-BLINKIT GROCERIES AND TOILETRIES ESSENTIALS | D17: 680 | F17: 10025 | G17: BLR02 | H17: =IF(C17="","",IF(E17>0,"INCOME",IF(D17>0,"EXPENSE","NEUTRAL"))) | I17: =IF(C17="","",=IF(OR(ISNUMBER(SEARCH("STIPEND",C17)),ISNUMBER(SEARCH("SIGMASOFT",C17)),ISNUMBER(SEARCH("SALARY",C17))),"Internship Stipend",IF(OR(ISNUMBER(SEARCH("FAMILY",C17)),ISNUMBER(SEARCH("PAPA",C17)),ISNUMBER(SEARCH("MOM",C17)),ISNUMBER(SEARCH("FATHER",C17))),"Family Support",IF(OR(ISNUMBER(SEARCH("PG",C17)),ISNUMBER(SEARCH("RENT",C17)),ISNUMBER(SEARCH("STANZA",C17)),ISNUMBER(SEARCH("ZOLO",C17))),"PG Rent & Covered Meals",IF(OR(ISNUMBER(SEARCH("GROWW",C17)),ISNUMBER(SEARCH("ZERODHA",C17)),ISNUMBER(SEARCH("MUTUAL",C17)),ISNUMBER(SEARCH("SIP",C17)),ISNUMBER(SEARCH("NIPPON",C17))),"Monthly SIP Investment",IF(OR(ISNUMBER(SEARCH("BMTC",C17)),ISNUMBER(SEARCH("BUS",C17)),ISNUMBER(SEARCH("METRO",C17)),ISNUMBER(SEARCH("CHALO",C17))),"BMTC Bus Commute",IF(OR(ISNUMBER(SEARCH("SWIGGY",C17)),ISNUMBER(SEARCH("ZOMATO",C17)),ISNUMBER(SEARCH("CANTEEN",C17)),ISNUMBER(SEARCH("LUNCH",C17)),ISNUMBER(SEARCH("FOOD",C17)),ISNUMBER(SEARCH("SUBWAY",C17))),"Daily Office Lunch (Mon–Sat)",IF(OR(ISNUMBER(SEARCH("BLINKIT",C17)),ISNUMBER(SEARCH("ZEPTO",C17)),ISNUMBER(SEARCH("RECHARGE",C17)),ISNUMBER(SEARCH("JIO",C17)),ISNUMBER(SEARCH("AIRTEL",C17)),ISNUMBER(SEARCH("PHARMACY",C17)),ISNUMBER(SEARCH("APOLLO",C17)),ISNUMBER(SEARCH("ESSENTIALS",C17)),ISNUMBER(SEARCH("LIFESTYLE",C17))),"Lifestyle & Personal Essentials",IF(OR(ISNUMBER(SEARCH("EMERGENCY",C17)),ISNUMBER(SEARCH("SWEEP",C17)),ISNUMBER(SEARCH("RESERVE",C17))),"Emergency Fund Allocation","Unallocated Flex Buffer"))))))))) | K17: =IF(C17="","",IF(J17<>"",J17,I17)) | L17: =IF(A17="","",IF(ISNUMBER(A17),TEXT(A17,"mmm-yyyy"),"Oct-2026")) | M17: =IF(D17>=5000,"🚨 High Value Debit (₹"&TEXT(D17,"#,##0")&")",IF(D17>=1000,"⚡ Notable Expense","—"))
A18: 11-10-2026 | B18: UPI550192 | C18: UPI-JIO FIBER & MOBILE PREPAID RECHARGE | D18: 499 | F18: 9526 | G18: MUM01 | H18: =IF(C18="","",IF(E18>0,"INCOME",IF(D18>0,"EXPENSE","NEUTRAL"))) | I18: =IF(C18="","",=IF(OR(ISNUMBER(SEARCH("STIPEND",C18)),ISNUMBER(SEARCH("SIGMASOFT",C18)),ISNUMBER(SEARCH("SALARY",C18))),"Internship Stipend",IF(OR(ISNUMBER(SEARCH("FAMILY",C18)),ISNUMBER(SEARCH("PAPA",C18)),ISNUMBER(SEARCH("MOM",C18)),ISNUMBER(SEARCH("FATHER",C18))),"Family Support",IF(OR(ISNUMBER(SEARCH("PG",C18)),ISNUMBER(SEARCH("RENT",C18)),ISNUMBER(SEARCH("STANZA",C18)),ISNUMBER(SEARCH("ZOLO",C18))),"PG Rent & Covered Meals",IF(OR(ISNUMBER(SEARCH("GROWW",C18)),ISNUMBER(SEARCH("ZERODHA",C18)),ISNUMBER(SEARCH("MUTUAL",C18)),ISNUMBER(SEARCH("SIP",C18)),ISNUMBER(SEARCH("NIPPON",C18))),"Monthly SIP Investment",IF(OR(ISNUMBER(SEARCH("BMTC",C18)),ISNUMBER(SEARCH("BUS",C18)),ISNUMBER(SEARCH("METRO",C18)),ISNUMBER(SEARCH("CHALO",C18))),"BMTC Bus Commute",IF(OR(ISNUMBER(SEARCH("SWIGGY",C18)),ISNUMBER(SEARCH("ZOMATO",C18)),ISNUMBER(SEARCH("CANTEEN",C18)),ISNUMBER(SEARCH("LUNCH",C18)),ISNUMBER(SEARCH("FOOD",C18)),ISNUMBER(SEARCH("SUBWAY",C18))),"Daily Office Lunch (Mon–Sat)",IF(OR(ISNUMBER(SEARCH("BLINKIT",C18)),ISNUMBER(SEARCH("ZEPTO",C18)),ISNUMBER(SEARCH("RECHARGE",C18)),ISNUMBER(SEARCH("JIO",C18)),ISNUMBER(SEARCH("AIRTEL",C18)),ISNUMBER(SEARCH("PHARMACY",C18)),ISNUMBER(SEARCH("APOLLO",C18)),ISNUMBER(SEARCH("ESSENTIALS",C18)),ISNUMBER(SEARCH("LIFESTYLE",C18))),"Lifestyle & Personal Essentials",IF(OR(ISNUMBER(SEARCH("EMERGENCY",C18)),ISNUMBER(SEARCH("SWEEP",C18)),ISNUMBER(SEARCH("RESERVE",C18))),"Emergency Fund Allocation","Unallocated Flex Buffer"))))))))) | K18: =IF(C18="","",IF(J18<>"",J18,I18)) | L18: =IF(A18="","",IF(ISNUMBER(A18),TEXT(A18,"mmm-yyyy"),"Oct-2026")) | M18: =IF(D18>=5000,"🚨 High Value Debit (₹"&TEXT(D18,"#,##0")&")",IF(D18>=1000,"⚡ Notable Expense","—"))
A19: 12-10-2026 | B19: UPI660394 | C19: UPI-APOLLO PHARMACY PERSONAL HEALTH ESSENTIALS | D19: 350 | F19: 9176 | G19: BLR02 | H19: =IF(C19="","",IF(E19>0,"INCOME",IF(D19>0,"EXPENSE","NEUTRAL"))) | I19: =IF(C19="","",=IF(OR(ISNUMBER(SEARCH("STIPEND",C19)),ISNUMBER(SEARCH("SIGMASOFT",C19)),ISNUMBER(SEARCH("SALARY",C19))),"Internship Stipend",IF(OR(ISNUMBER(SEARCH("FAMILY",C19)),ISNUMBER(SEARCH("PAPA",C19)),ISNUMBER(SEARCH("MOM",C19)),ISNUMBER(SEARCH("FATHER",C19))),"Family Support",IF(OR(ISNUMBER(SEARCH("PG",C19)),ISNUMBER(SEARCH("RENT",C19)),ISNUMBER(SEARCH("STANZA",C19)),ISNUMBER(SEARCH("ZOLO",C19))),"PG Rent & Covered Meals",IF(OR(ISNUMBER(SEARCH("GROWW",C19)),ISNUMBER(SEARCH("ZERODHA",C19)),ISNUMBER(SEARCH("MUTUAL",C19)),ISNUMBER(SEARCH("SIP",C19)),ISNUMBER(SEARCH("NIPPON",C19))),"Monthly SIP Investment",IF(OR(ISNUMBER(SEARCH("BMTC",C19)),ISNUMBER(SEARCH("BUS",C19)),ISNUMBER(SEARCH("METRO",C19)),ISNUMBER(SEARCH("CHALO",C19))),"BMTC Bus Commute",IF(OR(ISNUMBER(SEARCH("SWIGGY",C19)),ISNUMBER(SEARCH("ZOMATO",C19)),ISNUMBER(SEARCH("CANTEEN",C19)),ISNUMBER(SEARCH("LUNCH",C19)),ISNUMBER(SEARCH("FOOD",C19)),ISNUMBER(SEARCH("SUBWAY",C19))),"Daily Office Lunch (Mon–Sat)",IF(OR(ISNUMBER(SEARCH("BLINKIT",C19)),ISNUMBER(SEARCH("ZEPTO",C19)),ISNUMBER(SEARCH("RECHARGE",C19)),ISNUMBER(SEARCH("JIO",C19)),ISNUMBER(SEARCH("AIRTEL",C19)),ISNUMBER(SEARCH("PHARMACY",C19)),ISNUMBER(SEARCH("APOLLO",C19)),ISNUMBER(SEARCH("ESSENTIALS",C19)),ISNUMBER(SEARCH("LIFESTYLE",C19))),"Lifestyle & Personal Essentials",IF(OR(ISNUMBER(SEARCH("EMERGENCY",C19)),ISNUMBER(SEARCH("SWEEP",C19)),ISNUMBER(SEARCH("RESERVE",C19))),"Emergency Fund Allocation","Unallocated Flex Buffer"))))))))) | K19: =IF(C19="","",IF(J19<>"",J19,I19)) | L19: =IF(A19="","",IF(ISNUMBER(A19),TEXT(A19,"mmm-yyyy"),"Oct-2026")) | M19: =IF(D19>=5000,"🚨 High Value Debit (₹"&TEXT(D19,"#,##0")&")",IF(D19>=1000,"⚡ Notable Expense","—"))
... A23: 16-10-2026 | B23: ATM991823 | C23: ATM CASH WITHDRAWAL KUNDALAHALLI BRANCH | D23: 500 | F23: 7571 | G23: BLR01 | H23: =IF(C23="","",IF(E23>0,"INCOME",IF(D23>0,"EXPENSE","NEUTRAL"))) | I23: =IF(C23="","",=IF(OR(ISNUMBER(SEARCH("STIPEND",C23)),ISNUMBER(SEARCH("SIGMASOFT",C23)),ISNUMBER(SEARCH("SALARY",C23))),"Internship Stipend",IF(OR(ISNUMBER(SEARCH("FAMILY",C23)),ISNUMBER(SEARCH("PAPA",C23)),ISNUMBER(SEARCH("MOM",C23)),ISNUMBER(SEARCH("FATHER",C23))),"Family Support",IF(OR(ISNUMBER(SEARCH("PG",C23)),ISNUMBER(SEARCH("RENT",C23)),ISNUMBER(SEARCH("STANZA",C23)),ISNUMBER(SEARCH("ZOLO",C23))),"PG Rent & Covered Meals",IF(OR(ISNUMBER(SEARCH("GROWW",C23)),ISNUMBER(SEARCH("ZERODHA",C23)),ISNUMBER(SEARCH("MUTUAL",C23)),ISNUMBER(SEARCH("SIP",C23)),ISNUMBER(SEARCH("NIPPON",C23))),"Monthly SIP Investment",IF(OR(ISNUMBER(SEARCH("BMTC",C23)),ISNUMBER(SEARCH("BUS",C23)),ISNUMBER(SEARCH("METRO",C23)),ISNUMBER(SEARCH("CHALO",C23))),"BMTC Bus Commute",IF(OR(ISNUMBER(SEARCH("SWIGGY",C23)),ISNUMBER(SEARCH("ZOMATO",C23)),ISNUMBER(SEARCH("CANTEEN",C23)),ISNUMBER(SEARCH("LUNCH",C23)),ISNUMBER(SEARCH("FOOD",C23)),ISNUMBER(SEARCH("SUBWAY",C23))),"Daily Office Lunch (Mon–Sat)",IF(OR(ISNUMBER(SEARCH("BLINKIT",C23)),ISNUMBER(SEARCH("ZEPTO",C23)),ISNUMBER(SEARCH("RECHARGE",C23)),ISNUMBER(SEARCH("JIO",C23)),ISNUMBER(SEARCH("AIRTEL",C23)),ISNUMBER(SEARCH("PHARMACY",C23)),ISNUMBER(SEARCH("APOLLO",C23)),ISNUMBER(SEARCH("ESSENTIALS",C23)),ISNUMBER(SEARCH("LIFESTYLE",C23))),"Lifestyle & Personal Essentials",IF(OR(ISNUMBER(SEARCH("EMERGENCY",C23)),ISNUMBER(SEARCH("SWEEP",C23)),ISNUMBER(SEARCH("RESERVE",C23))),"Emergency Fund Allocation","Unallocated Flex Buffer"))))))))) | K23: =IF(C23="","",IF(J23<>"",J23,I23)) | L23: =IF(A23="","",IF(ISNUMBER(A23),TEXT(A23,"mmm-yyyy"),"Oct-2026")) | M23: =IF(D23>=5000,"🚨 High Value Debit (₹"&TEXT(D23,"#,##0")&")",IF(D23>=1000,"⚡ Notable Expense","—"))
H24: =IF(C24="","",IF(E24>0,"INCOME",IF(D24>0,"EXPENSE","NEUTRAL"))) | I24: =IF(C24="","",=IF(OR(ISNUMBER(SEARCH("STIPEND",C24)),ISNUMBER(SEARCH("SIGMASOFT",C24)),ISNUMBER(SEARCH("SALARY",C24))),"Internship Stipend",IF(OR(ISNUMBER(SEARCH("FAMILY",C24)),ISNUMBER(SEARCH("PAPA",C24)),ISNUMBER(SEARCH("MOM",C24)),ISNUMBER(SEARCH("FATHER",C24))),"Family Support",IF(OR(ISNUMBER(SEARCH("PG",C24)),ISNUMBER(SEARCH("RENT",C24)),ISNUMBER(SEARCH("STANZA",C24)),ISNUMBER(SEARCH("ZOLO",C24))),"PG Rent & Covered Meals",IF(OR(ISNUMBER(SEARCH("GROWW",C24)),ISNUMBER(SEARCH("ZERODHA",C24)),ISNUMBER(SEARCH("MUTUAL",C24)),ISNUMBER(SEARCH("SIP",C24)),ISNUMBER(SEARCH("NIPPON",C24))),"Monthly SIP Investment",IF(OR(ISNUMBER(SEARCH("BMTC",C24)),ISNUMBER(SEARCH("BUS",C24)),ISNUMBER(SEARCH("METRO",C24)),ISNUMBER(SEARCH("CHALO",C24))),"BMTC Bus Commute",IF(OR(ISNUMBER(SEARCH("SWIGGY",C24)),ISNUMBER(SEARCH("ZOMATO",C24)),ISNUMBER(SEARCH("CANTEEN",C24)),ISNUMBER(SEARCH("LUNCH",C24)),ISNUMBER(SEARCH("FOOD",C24)),ISNUMBER(SEARCH("SUBWAY",C24))),"Daily Office Lunch (Mon–Sat)",IF(OR(ISNUMBER(SEARCH("BLINKIT",C24)),ISNUMBER(SEARCH("ZEPTO",C24)),ISNUMBER(SEARCH("RECHARGE",C24)),ISNUMBER(SEARCH("JIO",C24)),ISNUMBER(SEARCH("AIRTEL",C24)),ISNUMBER(SEARCH("PHARMACY",C24)),ISNUMBER(SEARCH("APOLLO",C24)),ISNUMBER(SEARCH("ESSENTIALS",C24)),ISNUMBER(SEARCH("LIFESTYLE",C24))),"Lifestyle & Personal Essentials",IF(OR(ISNUMBER(SEARCH("EMERGENCY",C24)),ISNUMBER(SEARCH("SWEEP",C24)),ISNUMBER(SEARCH("RESERVE",C24))),"Emergency Fund Allocation","Unallocated Flex Buffer"))))))))) | K24: =IF(C24="","",IF(J24<>"",J24,I24)) | L24: =IF(A24="","",IF(ISNUMBER(A24),TEXT(A24,"mmm-yyyy"),"Oct-2026")) | M24: =IF(D24>=5000,"🚨 High Value Debit (₹"&TEXT(D24,"#,##0")&")",IF(D24>=1000,"⚡ Notable Expense","—"))
H25: =IF(C25="","",IF(E25>0,"INCOME",IF(D25>0,"EXPENSE","NEUTRAL"))) | I25: =IF(C25="","",=IF(OR(ISNUMBER(SEARCH("STIPEND",C25)),ISNUMBER(SEARCH("SIGMASOFT",C25)),ISNUMBER(SEARCH("SALARY",C25))),"Internship Stipend",IF(OR(ISNUMBER(SEARCH("FAMILY",C25)),ISNUMBER(SEARCH("PAPA",C25)),ISNUMBER(SEARCH("MOM",C25)),ISNUMBER(SEARCH("FATHER",C25))),"Family Support",IF(OR(ISNUMBER(SEARCH("PG",C25)),ISNUMBER(SEARCH("RENT",C25)),ISNUMBER(SEARCH("STANZA",C25)),ISNUMBER(SEARCH("ZOLO",C25))),"PG Rent & Covered Meals",IF(OR(ISNUMBER(SEARCH("GROWW",C25)),ISNUMBER(SEARCH("ZERODHA",C25)),ISNUMBER(SEARCH("MUTUAL",C25)),ISNUMBER(SEARCH("SIP",C25)),ISNUMBER(SEARCH("NIPPON",C25))),"Monthly SIP Investment",IF(OR(ISNUMBER(SEARCH("BMTC",C25)),ISNUMBER(SEARCH("BUS",C25)),ISNUMBER(SEARCH("METRO",C25)),ISNUMBER(SEARCH("CHALO",C25))),"BMTC Bus Commute",IF(OR(ISNUMBER(SEARCH("SWIGGY",C25)),ISNUMBER(SEARCH("ZOMATO",C25)),ISNUMBER(SEARCH("CANTEEN",C25)),ISNUMBER(SEARCH("LUNCH",C25)),ISNUMBER(SEARCH("FOOD",C25)),ISNUMBER(SEARCH("SUBWAY",C25))),"Daily Office Lunch (Mon–Sat)",IF(OR(ISNUMBER(SEARCH("BLINKIT",C25)),ISNUMBER(SEARCH("ZEPTO",C25)),ISNUMBER(SEARCH("RECHARGE",C25)),ISNUMBER(SEARCH("JIO",C25)),ISNUMBER(SEARCH("AIRTEL",C25)),ISNUMBER(SEARCH("PHARMACY",C25)),ISNUMBER(SEARCH("APOLLO",C25)),ISNUMBER(SEARCH("ESSENTIALS",C25)),ISNUMBER(SEARCH("LIFESTYLE",C25))),"Lifestyle & Personal Essentials",IF(OR(ISNUMBER(SEARCH("EMERGENCY",C25)),ISNUMBER(SEARCH("SWEEP",C25)),ISNUMBER(SEARCH("RESERVE",C25))),"Emergency Fund Allocation","Unallocated Flex Buffer"))))))))) | K25: =IF(C25="","",IF(J25<>"",J25,I25)) | L25: =IF(A25="","",IF(ISNUMBER(A25),TEXT(A25,"mmm-yyyy"),"Oct-2026")) | M25: =IF(D25>=5000,"🚨 High Value Debit (₹"&TEXT(D25,"#,##0")&")",IF(D25>=1000,"⚡ Notable Expense","—"))
H26: =IF(C26="","",IF(E26>0,"INCOME",IF(D26>0,"EXPENSE","NEUTRAL"))) | I26: =IF(C26="","",=IF(OR(ISNUMBER(SEARCH("STIPEND",C26)),ISNUMBER(SEARCH("SIGMASOFT",C26)),ISNUMBER(SEARCH("SALARY",C26))),"Internship Stipend",IF(OR(ISNUMBER(SEARCH("FAMILY",C26)),ISNUMBER(SEARCH("PAPA",C26)),ISNUMBER(SEARCH("MOM",C26)),ISNUMBER(SEARCH("FATHER",C26))),"Family Support",IF(OR(ISNUMBER(SEARCH("PG",C26)),ISNUMBER(SEARCH("RENT",C26)),ISNUMBER(SEARCH("STANZA",C26)),ISNUMBER(SEARCH("ZOLO",C26))),"PG Rent & Covered Meals",IF(OR(ISNUMBER(SEARCH("GROWW",C26)),ISNUMBER(SEARCH("ZERODHA",C26)),ISNUMBER(SEARCH("MUTUAL",C26)),ISNUMBER(SEARCH("SIP",C26)),ISNUMBER(SEARCH("NIPPON",C26))),"Monthly SIP Investment",IF(OR(ISNUMBER(SEARCH("BMTC",C26)),ISNUMBER(SEARCH("BUS",C26)),ISNUMBER(SEARCH("METRO",C26)),ISNUMBER(SEARCH("CHALO",C26))),"BMTC Bus Commute",IF(OR(ISNUMBER(SEARCH("SWIGGY",C26)),ISNUMBER(SEARCH("ZOMATO",C26)),ISNUMBER(SEARCH("CANTEEN",C26)),ISNUMBER(SEARCH("LUNCH",C26)),ISNUMBER(SEARCH("FOOD",C26)),ISNUMBER(SEARCH("SUBWAY",C26))),"Daily Office Lunch (Mon–Sat)",IF(OR(ISNUMBER(SEARCH("BLINKIT",C26)),ISNUMBER(SEARCH("ZEPTO",C26)),ISNUMBER(SEARCH("RECHARGE",C26)),ISNUMBER(SEARCH("JIO",C26)),ISNUMBER(SEARCH("AIRTEL",C26)),ISNUMBER(SEARCH("PHARMACY",C26)),ISNUMBER(SEARCH("APOLLO",C26)),ISNUMBER(SEARCH("ESSENTIALS",C26)),ISNUMBER(SEARCH("LIFESTYLE",C26))),"Lifestyle & Personal Essentials",IF(OR(ISNUMBER(SEARCH("EMERGENCY",C26)),ISNUMBER(SEARCH("SWEEP",C26)),ISNUMBER(SEARCH("RESERVE",C26))),"Emergency Fund Allocation","Unallocated Flex Buffer"))))))))) | K26: =IF(C26="","",IF(J26<>"",J26,I26)) | L26: =IF(A26="","",IF(ISNUMBER(A26),TEXT(A26,"mmm-yyyy"),"Oct-2026")) | M26: =IF(D26>=5000,"🚨 High Value Debit (₹"&TEXT(D26,"#,##0")&")",IF(D26>=1000,"⚡ Notable Expense","—"))
H27: =IF(C27="","",IF(E27>0,"INCOME",IF(D27>0,"EXPENSE","NEUTRAL"))) | I27: =IF(C27="","",=IF(OR(ISNUMBER(SEARCH("STIPEND",C27)),ISNUMBER(SEARCH("SIGMASOFT",C27)),ISNUMBER(SEARCH("SALARY",C27))),"Internship Stipend",IF(OR(ISNUMBER(SEARCH("FAMILY",C27)),ISNUMBER(SEARCH("PAPA",C27)),ISNUMBER(SEARCH("MOM",C27)),ISNUMBER(SEARCH("FATHER",C27))),"Family Support",IF(OR(ISNUMBER(SEARCH("PG",C27)),ISNUMBER(SEARCH("RENT",C27)),ISNUMBER(SEARCH("STANZA",C27)),ISNUMBER(SEARCH("ZOLO",C27))),"PG Rent & Covered Meals",IF(OR(ISNUMBER(SEARCH("GROWW",C27)),ISNUMBER(SEARCH("ZERODHA",C27)),ISNUMBER(SEARCH("MUTUAL",C27)),ISNUMBER(SEARCH("SIP",C27)),ISNUMBER(SEARCH("NIPPON",C27))),"Monthly SIP Investment",IF(OR(ISNUMBER(SEARCH("BMTC",C27)),ISNUMBER(SEARCH("BUS",C27)),ISNUMBER(SEARCH("METRO",C27)),ISNUMBER(SEARCH("CHALO",C27))),"BMTC Bus Commute",IF(OR(ISNUMBER(SEARCH("SWIGGY",C27)),ISNUMBER(SEARCH("ZOMATO",C27)),ISNUMBER(SEARCH("CANTEEN",C27)),ISNUMBER(SEARCH("LUNCH",C27)),ISNUMBER(SEARCH("FOOD",C27)),ISNUMBER(SEARCH("SUBWAY",C27))),"Daily Office Lunch (Mon–Sat)",IF(OR(ISNUMBER(SEARCH("BLINKIT",C27)),ISNUMBER(SEARCH("ZEPTO",C27)),ISNUMBER(SEARCH("RECHARGE",C27)),ISNUMBER(SEARCH("JIO",C27)),ISNUMBER(SEARCH("AIRTEL",C27)),ISNUMBER(SEARCH("PHARMACY",C27)),ISNUMBER(SEARCH("APOLLO",C27)),ISNUMBER(SEARCH("ESSENTIALS",C27)),ISNUMBER(SEARCH("LIFESTYLE",C27))),"Lifestyle & Personal Essentials",IF(OR(ISNUMBER(SEARCH("EMERGENCY",C27)),ISNUMBER(SEARCH("SWEEP",C27)),ISNUMBER(SEARCH("RESERVE",C27))),"Emergency Fund Allocation","Unallocated Flex Buffer"))))))))) | K27: =IF(C27="","",IF(J27<>"",J27,I27)) | L27: =IF(A27="","",IF(ISNUMBER(A27),TEXT(A27,"mmm-yyyy"),"Oct-2026")) | M27: =IF(D27>=5000,"🚨 High Value Debit (₹"&TEXT(D27,"#,##0")&")",IF(D27>=1000,"⚡ Notable Expense","—"))
H28: =IF(C28="","",IF(E28>0,"INCOME",IF(D28>0,"EXPENSE","NEUTRAL"))) | I28: =IF(C28="","",=IF(OR(ISNUMBER(SEARCH("STIPEND",C28)),ISNUMBER(SEARCH("SIGMASOFT",C28)),ISNUMBER(SEARCH("SALARY",C28))),"Internship Stipend",IF(OR(ISNUMBER(SEARCH("FAMILY",C28)),ISNUMBER(SEARCH("PAPA",C28)),ISNUMBER(SEARCH("MOM",C28)),ISNUMBER(SEARCH("FATHER",C28))),"Family Support",IF(OR(ISNUMBER(SEARCH("PG",C28)),ISNUMBER(SEARCH("RENT",C28)),ISNUMBER(SEARCH("STANZA",C28)),ISNUMBER(SEARCH("ZOLO",C28))),"PG Rent & Covered Meals",IF(OR(ISNUMBER(SEARCH("GROWW",C28)),ISNUMBER(SEARCH("ZERODHA",C28)),ISNUMBER(SEARCH("MUTUAL",C28)),ISNUMBER(SEARCH("SIP",C28)),ISNUMBER(SEARCH("NIPPON",C28))),"Monthly SIP Investment",IF(OR(ISNUMBER(SEARCH("BMTC",C28)),ISNUMBER(SEARCH("BUS",C28)),ISNUMBER(SEARCH("METRO",C28)),ISNUMBER(SEARCH("CHALO",C28))),"BMTC Bus Commute",IF(OR(ISNUMBER(SEARCH("SWIGGY",C28)),ISNUMBER(SEARCH("ZOMATO",C28)),ISNUMBER(SEARCH("CANTEEN",C28)),ISNUMBER(SEARCH("LUNCH",C28)),ISNUMBER(SEARCH("FOOD",C28)),ISNUMBER(SEARCH("SUBWAY",C28))),"Daily Office Lunch (Mon–Sat)",IF(OR(ISNUMBER(SEARCH("BLINKIT",C28)),ISNUMBER(SEARCH("ZEPTO",C28)),ISNUMBER(SEARCH("RECHARGE",C28)),ISNUMBER(SEARCH("JIO",C28)),ISNUMBER(SEARCH("AIRTEL",C28)),ISNUMBER(SEARCH("PHARMACY",C28)),ISNUMBER(SEARCH("APOLLO",C28)),ISNUMBER(SEARCH("ESSENTIALS",C28)),ISNUMBER(SEARCH("LIFESTYLE",C28))),"Lifestyle & Personal Essentials",IF(OR(ISNUMBER(SEARCH("EMERGENCY",C28)),ISNUMBER(SEARCH("SWEEP",C28)),ISNUMBER(SEARCH("RESERVE",C28))),"Emergency Fund Allocation","Unallocated Flex Buffer"))))))))) | K28: =IF(C28="","",IF(J28<>"",J28,I28)) | L28: =IF(A28="","",IF(ISNUMBER(A28),TEXT(A28,"mmm-yyyy"),"Oct-2026")) | M28: =IF(D28>=5000,"🚨 High Value Debit (₹"&TEXT(D28,"#,##0")&")",IF(D28>=1000,"⚡ Notable Expense","—"))
H29: =IF(C29="","",IF(E29>0,"INCOME",IF(D29>0,"EXPENSE","NEUTRAL"))) | I29: =IF(C29="","",=IF(OR(ISNUMBER(SEARCH("STIPEND",C29)),ISNUMBER(SEARCH("SIGMASOFT",C29)),ISNUMBER(SEARCH("SALARY",C29))),"Internship Stipend",IF(OR(ISNUMBER(SEARCH("FAMILY",C29)),ISNUMBER(SEARCH("PAPA",C29)),ISNUMBER(SEARCH("MOM",C29)),ISNUMBER(SEARCH("FATHER",C29))),"Family Support",IF(OR(ISNUMBER(SEARCH("PG",C29)),ISNUMBER(SEARCH("RENT",C29)),ISNUMBER(SEARCH("STANZA",C29)),ISNUMBER(SEARCH("ZOLO",C29))),"PG Rent & Covered Meals",IF(OR(ISNUMBER(SEARCH("GROWW",C29)),ISNUMBER(SEARCH("ZERODHA",C29)),ISNUMBER(SEARCH("MUTUAL",C29)),ISNUMBER(SEARCH("SIP",C29)),ISNUMBER(SEARCH("NIPPON",C29))),"Monthly SIP Investment",IF(OR(ISNUMBER(SEARCH("BMTC",C29)),ISNUMBER(SEARCH("BUS",C29)),ISNUMBER(SEARCH("METRO",C29)),ISNUMBER(SEARCH("CHALO",C29))),"BMTC Bus Commute",IF(OR(ISNUMBER(SEARCH("SWIGGY",C29)),ISNUMBER(SEARCH("ZOMATO",C29)),ISNUMBER(SEARCH("CANTEEN",C29)),ISNUMBER(SEARCH("LUNCH",C29)),ISNUMBER(SEARCH("FOOD",C29)),ISNUMBER(SEARCH("SUBWAY",C29))),"Daily Office Lunch (Mon–Sat)",IF(OR(ISNUMBER(SEARCH("BLINKIT",C29)),ISNUMBER(SEARCH("ZEPTO",C29)),ISNUMBER(SEARCH("RECHARGE",C29)),ISNUMBER(SEARCH("JIO",C29)),ISNUMBER(SEARCH("AIRTEL",C29)),ISNUMBER(SEARCH("PHARMACY",C29)),ISNUMBER(SEARCH("APOLLO",C29)),ISNUMBER(SEARCH("ESSENTIALS",C29)),ISNUMBER(SEARCH("LIFESTYLE",C29))),"Lifestyle & Personal Essentials",IF(OR(ISNUMBER(SEARCH("EMERGENCY",C29)),ISNUMBER(SEARCH("SWEEP",C29)),ISNUMBER(SEARCH("RESERVE",C29))),"Emergency Fund Allocation","Unallocated Flex Buffer"))))))))) | K29: =IF(C29="","",IF(J29<>"",J29,I29)) | L29: =IF(A29="","",IF(ISNUMBER(A29),TEXT(A29,"mmm-yyyy"),"Oct-2026")) | M29: =IF(D29>=5000,"🚨 High Value Debit (₹"&TEXT(D29,"#,##0")&")",IF(D29>=1000,"⚡ Notable Expense","—"))
H30: =IF(C30="","",IF(E30>0,"INCOME",IF(D30>0,"EXPENSE","NEUTRAL"))) | I30: =IF(C30="","",=IF(OR(ISNUMBER(SEARCH("STIPEND",C30)),ISNUMBER(SEARCH("SIGMASOFT",C30)),ISNUMBER(SEARCH("SALARY",C30))),"Internship Stipend",IF(OR(ISNUMBER(SEARCH("FAMILY",C30)),ISNUMBER(SEARCH("PAPA",C30)),ISNUMBER(SEARCH("MOM",C30)),ISNUMBER(SEARCH("FATHER",C30))),"Family Support",IF(OR(ISNUMBER(SEARCH("PG",C30)),ISNUMBER(SEARCH("RENT",C30)),ISNUMBER(SEARCH("STANZA",C30)),ISNUMBER(SEARCH("ZOLO",C30))),"PG Rent & Covered Meals",IF(OR(ISNUMBER(SEARCH("GROWW",C30)),ISNUMBER(SEARCH("ZERODHA",C30)),ISNUMBER(SEARCH("MUTUAL",C30)),ISNUMBER(SEARCH("SIP",C30)),ISNUMBER(SEARCH("NIPPON",C30))),"Monthly SIP Investment",IF(OR(ISNUMBER(SEARCH("BMTC",C30)),ISNUMBER(SEARCH("BUS",C30)),ISNUMBER(SEARCH("METRO",C30)),ISNUMBER(SEARCH("CHALO",C30))),"BMTC Bus Commute",IF(OR(ISNUMBER(SEARCH("SWIGGY",C30)),ISNUMBER(SEARCH("ZOMATO",C30)),ISNUMBER(SEARCH("CANTEEN",C30)),ISNUMBER(SEARCH("LUNCH",C30)),ISNUMBER(SEARCH("FOOD",C30)),ISNUMBER(SEARCH("SUBWAY",C30))),"Daily Office Lunch (Mon–Sat)",IF(OR(ISNUMBER(SEARCH("BLINKIT",C30)),ISNUMBER(SEARCH("ZEPTO",C30)),ISNUMBER(SEARCH("RECHARGE",C30)),ISNUMBER(SEARCH("JIO",C30)),ISNUMBER(SEARCH("AIRTEL",C30)),ISNUMBER(SEARCH("PHARMACY",C30)),ISNUMBER(SEARCH("APOLLO",C30)),ISNUMBER(SEARCH("ESSENTIALS",C30)),ISNUMBER(SEARCH("LIFESTYLE",C30))),"Lifestyle & Personal Essentials",IF(OR(ISNUMBER(SEARCH("EMERGENCY",C30)),ISNUMBER(SEARCH("SWEEP",C30)),ISNUMBER(SEARCH("RESERVE",C30))),"Emergency Fund Allocation","Unallocated Flex Buffer"))))))))) | K30: =IF(C30="","",IF(J30<>"",J30,I30)) | L30: =IF(A30="","",IF(ISNUMBER(A30),TEXT(A30,"mmm-yyyy"),"Oct-2026")) | M30: =IF(D30>=5000,"🚨 High Value Debit (₹"&TEXT(D30,"#,##0")&")",IF(D30>=1000,"⚡ Notable Expense","—"))
H31: =IF(C31="","",IF(E31>0,"INCOME",IF(D31>0,"EXPENSE","NEUTRAL"))) | I31: =IF(C31="","",=IF(OR(ISNUMBER(SEARCH("STIPEND",C31)),ISNUMBER(SEARCH("SIGMASOFT",C31)),ISNUMBER(SEARCH("SALARY",C31))),"Internship Stipend",IF(OR(ISNUMBER(SEARCH("FAMILY",C31)),ISNUMBER(SEARCH("PAPA",C31)),ISNUMBER(SEARCH("MOM",C31)),ISNUMBER(SEARCH("FATHER",C31))),"Family Support",IF(OR(ISNUMBER(SEARCH("PG",C31)),ISNUMBER(SEARCH("RENT",C31)),ISNUMBER(SEARCH("STANZA",C31)),ISNUMBER(SEARCH("ZOLO",C31))),"PG Rent & Covered Meals",IF(OR(ISNUMBER(SEARCH("GROWW",C31)),ISNUMBER(SEARCH("ZERODHA",C31)),ISNUMBER(SEARCH("MUTUAL",C31)),ISNUMBER(SEARCH("SIP",C31)),ISNUMBER(SEARCH("NIPPON",C31))),"Monthly SIP Investment",IF(OR(ISNUMBER(SEARCH("BMTC",C31)),ISNUMBER(SEARCH("BUS",C31)),ISNUMBER(SEARCH("METRO",C31)),ISNUMBER(SEARCH("CHALO",C31))),"BMTC Bus Commute",IF(OR(ISNUMBER(SEARCH("SWIGGY",C31)),ISNUMBER(SEARCH("ZOMATO",C31)),ISNUMBER(SEARCH("CANTEEN",C31)),ISNUMBER(SEARCH("LUNCH",C31)),ISNUMBER(SEARCH("FOOD",C31)),ISNUMBER(SEARCH("SUBWAY",C31))),"Daily Office Lunch (Mon–Sat)",IF(OR(ISNUMBER(SEARCH("BLINKIT",C31)),ISNUMBER(SEARCH("ZEPTO",C31)),ISNUMBER(SEARCH("RECHARGE",C31)),ISNUMBER(SEARCH("JIO",C31)),ISNUMBER(SEARCH("AIRTEL",C31)),ISNUMBER(SEARCH("PHARMACY",C31)),ISNUMBER(SEARCH("APOLLO",C31)),ISNUMBER(SEARCH("ESSENTIALS",C31)),ISNUMBER(SEARCH("LIFESTYLE",C31))),"Lifestyle & Personal Essentials",IF(OR(ISNUMBER(SEARCH("EMERGENCY",C31)),ISNUMBER(SEARCH("SWEEP",C31)),ISNUMBER(SEARCH("RESERVE",C31))),"Emergency Fund Allocation","Unallocated Flex Buffer"))))))))) | K31: =IF(C31="","",IF(J31<>"",J31,I31)) | L31: =IF(A31="","",IF(ISNUMBER(A31),TEXT(A31,"mmm-yyyy"),"Oct-2026")) | M31: =IF(D31>=5000,"🚨 High Value Debit (₹"&TEXT(D31,"#,##0")&")",IF(D31>=1000,"⚡ Notable Expense","—"))
H32: =IF(C32="","",IF(E32>0,"INCOME",IF(D32>0,"EXPENSE","NEUTRAL"))) | I32: =IF(C32="","",=IF(OR(ISNUMBER(SEARCH("STIPEND",C32)),ISNUMBER(SEARCH("SIGMASOFT",C32)),ISNUMBER(SEARCH("SALARY",C32))),"Internship Stipend",IF(OR(ISNUMBER(SEARCH("FAMILY",C32)),ISNUMBER(SEARCH("PAPA",C32)),ISNUMBER(SEARCH("MOM",C32)),ISNUMBER(SEARCH("FATHER",C32))),"Family Support",IF(OR(ISNUMBER(SEARCH("PG",C32)),ISNUMBER(SEARCH("RENT",C32)),ISNUMBER(SEARCH("STANZA",C32)),ISNUMBER(SEARCH("ZOLO",C32))),"PG Rent & Covered Meals",IF(OR(ISNUMBER(SEARCH("GROWW",C32)),ISNUMBER(SEARCH("ZERODHA",C32)),ISNUMBER(SEARCH("MUTUAL",C32)),ISNUMBER(SEARCH("SIP",C32)),ISNUMBER(SEARCH("NIPPON",C32))),"Monthly SIP Investment",IF(OR(ISNUMBER(SEARCH("BMTC",C32)),ISNUMBER(SEARCH("BUS",C32)),ISNUMBER(SEARCH("METRO",C32)),ISNUMBER(SEARCH("CHALO",C32))),"BMTC Bus Commute",IF(OR(ISNUMBER(SEARCH("SWIGGY",C32)),ISNUMBER(SEARCH("ZOMATO",C32)),ISNUMBER(SEARCH("CANTEEN",C32)),ISNUMBER(SEARCH("LUNCH",C32)),ISNUMBER(SEARCH("FOOD",C32)),ISNUMBER(SEARCH("SUBWAY",C32))),"Daily Office Lunch (Mon–Sat)",IF(OR(ISNUMBER(SEARCH("BLINKIT",C32)),ISNUMBER(SEARCH("ZEPTO",C32)),ISNUMBER(SEARCH("RECHARGE",C32)),ISNUMBER(SEARCH("JIO",C32)),ISNUMBER(SEARCH("AIRTEL",C32)),ISNUMBER(SEARCH("PHARMACY",C32)),ISNUMBER(SEARCH("APOLLO",C32)),ISNUMBER(SEARCH("ESSENTIALS",C32)),ISNUMBER(SEARCH("LIFESTYLE",C32))),"Lifestyle & Personal Essentials",IF(OR(ISNUMBER(SEARCH("EMERGENCY",C32)),ISNUMBER(SEARCH("SWEEP",C32)),ISNUMBER(SEARCH("RESERVE",C32))),"Emergency Fund Allocation","Unallocated Flex Buffer"))))))))) | K32: =IF(C32="","",IF(J32<>"",J32,I32)) | L32: =IF(A32="","",IF(ISNUMBER(A32),TEXT(A32,"mmm-yyyy"),"Oct-2026")) | M32: =IF(D32>=5000,"🚨 High Value Debit (₹"&TEXT(D32,"#,##0")&")",IF(D32>=1000,"⚡ Notable Expense","—"))
H33: =IF(C33="","",IF(E33>0,"INCOME",IF(D33>0,"EXPENSE","NEUTRAL"))) | I33: =IF(C33="","",=IF(OR(ISNUMBER(SEARCH("STIPEND",C33)),ISNUMBER(SEARCH("SIGMASOFT",C33)),ISNUMBER(SEARCH("SALARY",C33))),"Internship Stipend",IF(OR(ISNUMBER(SEARCH("FAMILY",C33)),ISNUMBER(SEARCH("PAPA",C33)),ISNUMBER(SEARCH("MOM",C33)),ISNUMBER(SEARCH("FATHER",C33))),"Family Support",IF(OR(ISNUMBER(SEARCH("PG",C33)),ISNUMBER(SEARCH("RENT",C33)),ISNUMBER(SEARCH("STANZA",C33)),ISNUMBER(SEARCH("ZOLO",C33))),"PG Rent & Covered Meals",IF(OR(ISNUMBER(SEARCH("GROWW",C33)),ISNUMBER(SEARCH("ZERODHA",C33)),ISNUMBER(SEARCH("MUTUAL",C33)),ISNUMBER(SEARCH("SIP",C33)),ISNUMBER(SEARCH("NIPPON",C33))),"Monthly SIP Investment",IF(OR(ISNUMBER(SEARCH("BMTC",C33)),ISNUMBER(SEARCH("BUS",C33)),ISNUMBER(SEARCH("METRO",C33)),ISNUMBER(SEARCH("CHALO",C33))),"BMTC Bus Commute",IF(OR(ISNUMBER(SEARCH("SWIGGY",C33)),ISNUMBER(SEARCH("ZOMATO",C33)),ISNUMBER(SEARCH("CANTEEN",C33)),ISNUMBER(SEARCH("LUNCH",C33)),ISNUMBER(SEARCH("FOOD",C33)),ISNUMBER(SEARCH("SUBWAY",C33))),"Daily Office Lunch (Mon–Sat)",IF(OR(ISNUMBER(SEARCH("BLINKIT",C33)),ISNUMBER(SEARCH("ZEPTO",C33)),ISNUMBER(SEARCH("RECHARGE",C33)),ISNUMBER(SEARCH("JIO",C33)),ISNUMBER(SEARCH("AIRTEL",C33)),ISNUMBER(SEARCH("PHARMACY",C33)),ISNUMBER(SEARCH("APOLLO",C33)),ISNUMBER(SEARCH("ESSENTIALS",C33)),ISNUMBER(SEARCH("LIFESTYLE",C33))),"Lifestyle & Personal Essentials",IF(OR(ISNUMBER(SEARCH("EMERGENCY",C33)),ISNUMBER(SEARCH("SWEEP",C33)),ISNUMBER(SEARCH("RESERVE",C33))),"Emergency Fund Allocation","Unallocated Flex Buffer"))))))))) | K33: =IF(C33="","",IF(J33<>"",J33,I33)) | L33: =IF(A33="","",IF(ISNUMBER(A33),TEXT(A33,"mmm-yyyy"),"Oct-2026")) | M33: =IF(D33>=5000,"🚨 High Value Debit (₹"&TEXT(D33,"#,##0")&")",IF(D33>=1000,"⚡ Notable Expense","—"))
H34: =IF(C34="","",IF(E34>0,"INCOME",IF(D34>0,"EXPENSE","NEUTRAL"))) | I34: =IF(C34="","",=IF(OR(ISNUMBER(SEARCH("STIPEND",C34)),ISNUMBER(SEARCH("SIGMASOFT",C34)),ISNUMBER(SEARCH("SALARY",C34))),"Internship Stipend",IF(OR(ISNUMBER(SEARCH("FAMILY",C34)),ISNUMBER(SEARCH("PAPA",C34)),ISNUMBER(SEARCH("MOM",C34)),ISNUMBER(SEARCH("FATHER",C34))),"Family Support",IF(OR(ISNUMBER(SEARCH("PG",C34)),ISNUMBER(SEARCH("RENT",C34)),ISNUMBER(SEARCH("STANZA",C34)),ISNUMBER(SEARCH("ZOLO",C34))),"PG Rent & Covered Meals",IF(OR(ISNUMBER(SEARCH("GROWW",C34)),ISNUMBER(SEARCH("ZERODHA",C34)),ISNUMBER(SEARCH("MUTUAL",C34)),ISNUMBER(SEARCH("SIP",C34)),ISNUMBER(SEARCH("NIPPON",C34))),"Monthly SIP Investment",IF(OR(ISNUMBER(SEARCH("BMTC",C34)),ISNUMBER(SEARCH("BUS",C34)),ISNUMBER(SEARCH("METRO",C34)),ISNUMBER(SEARCH("CHALO",C34))),"BMTC Bus Commute",IF(OR(ISNUMBER(SEARCH("SWIGGY",C34)),ISNUMBER(SEARCH("ZOMATO",C34)),ISNUMBER(SEARCH("CANTEEN",C34)),ISNUMBER(SEARCH("LUNCH",C34)),ISNUMBER(SEARCH("FOOD",C34)),ISNUMBER(SEARCH("SUBWAY",C34))),"Daily Office Lunch (Mon–Sat)",IF(OR(ISNUMBER(SEARCH("BLINKIT",C34)),ISNUMBER(SEARCH("ZEPTO",C34)),ISNUMBER(SEARCH("RECHARGE",C34)),ISNUMBER(SEARCH("JIO",C34)),ISNUMBER(SEARCH("AIRTEL",C34)),ISNUMBER(SEARCH("PHARMACY",C34)),ISNUMBER(SEARCH("APOLLO",C34)),ISNUMBER(SEARCH("ESSENTIALS",C34)),ISNUMBER(SEARCH("LIFESTYLE",C34))),"Lifestyle & Personal Essentials",IF(OR(ISNUMBER(SEARCH("EMERGENCY",C34)),ISNUMBER(SEARCH("SWEEP",C34)),ISNUMBER(SEARCH("RESERVE",C34))),"Emergency Fund Allocation","Unallocated Flex Buffer"))))))))) | K34: =IF(C34="","",IF(J34<>"",J34,I34)) | L34: =IF(A34="","",IF(ISNUMBER(A34),TEXT(A34,"mmm-yyyy"),"Oct-2026")) | M34: =IF(D34>=5000,"🚨 High Value Debit (₹"&TEXT(D34,"#,##0")&")",IF(D34>=1000,"⚡ Notable Expense","—"))
H35: =IF(C35="","",IF(E35>0,"INCOME",IF(D35>0,"EXPENSE","NEUTRAL"))) | I35: =IF(C35="","",=IF(OR(ISNUMBER(SEARCH("STIPEND",C35)),ISNUMBER(SEARCH("SIGMASOFT",C35)),ISNUMBER(SEARCH("SALARY",C35))),"Internship Stipend",IF(OR(ISNUMBER(SEARCH("FAMILY",C35)),ISNUMBER(SEARCH("PAPA",C35)),ISNUMBER(SEARCH("MOM",C35)),ISNUMBER(SEARCH("FATHER",C35))),"Family Support",IF(OR(ISNUMBER(SEARCH("PG",C35)),ISNUMBER(SEARCH("RENT",C35)),ISNUMBER(SEARCH("STANZA",C35)),ISNUMBER(SEARCH("ZOLO",C35))),"PG Rent & Covered Meals",IF(OR(ISNUMBER(SEARCH("GROWW",C35)),ISNUMBER(SEARCH("ZERODHA",C35)),ISNUMBER(SEARCH("MUTUAL",C35)),ISNUMBER(SEARCH("SIP",C35)),ISNUMBER(SEARCH("NIPPON",C35))),"Monthly SIP Investment",IF(OR(ISNUMBER(SEARCH("BMTC",C35)),ISNUMBER(SEARCH("BUS",C35)),ISNUMBER(SEARCH("METRO",C35)),ISNUMBER(SEARCH("CHALO",C35))),"BMTC Bus Commute",IF(OR(ISNUMBER(SEARCH("SWIGGY",C35)),ISNUMBER(SEARCH("ZOMATO",C35)),ISNUMBER(SEARCH("CANTEEN",C35)),ISNUMBER(SEARCH("LUNCH",C35)),ISNUMBER(SEARCH("FOOD",C35)),ISNUMBER(SEARCH("SUBWAY",C35))),"Daily Office Lunch (Mon–Sat)",IF(OR(ISNUMBER(SEARCH("BLINKIT",C35)),ISNUMBER(SEARCH("ZEPTO",C35)),ISNUMBER(SEARCH("RECHARGE",C35)),ISNUMBER(SEARCH("JIO",C35)),ISNUMBER(SEARCH("AIRTEL",C35)),ISNUMBER(SEARCH("PHARMACY",C35)),ISNUMBER(SEARCH("APOLLO",C35)),ISNUMBER(SEARCH("ESSENTIALS",C35)),ISNUMBER(SEARCH("LIFESTYLE",C35))),"Lifestyle & Personal Essentials",IF(OR(ISNUMBER(SEARCH("EMERGENCY",C35)),ISNUMBER(SEARCH("SWEEP",C35)),ISNUMBER(SEARCH("RESERVE",C35))),"Emergency Fund Allocation","Unallocated Flex Buffer"))))))))) | K35: =IF(C35="","",IF(J35<>"",J35,I35)) | L35: =IF(A35="","",IF(ISNUMBER(A35),TEXT(A35,"mmm-yyyy"),"Oct-2026")) | M35: =IF(D35>=5000,"🚨 High Value Debit (₹"&TEXT(D35,"#,##0")&")",IF(D35>=1000,"⚡ Notable Expense","—"))
... H255: =IF(C255="","",IF(E255>0,"INCOME",IF(D255>0,"EXPENSE","NEUTRAL"))) | I255: =IF(C255="","",=IF(OR(ISNUMBER(SEARCH("STIPEND",C255)),ISNUMBER(SEARCH("SIGMASOFT",C255)),ISNUMBER(SEARCH("SALARY",C255))),"Internship Stipend",IF(OR(ISNUMBER(SEARCH("FAMILY",C255)),ISNUMBER(SEARCH("PAPA",C255)),ISNUMBER(SEARCH("MOM",C255)),ISNUMBER(SEARCH("FATHER",C255))),"Family Support",IF(OR(ISNUMBER(SEARCH("PG",C255)),ISNUMBER(SEARCH("RENT",C255)),ISNUMBER(SEARCH("STANZA",C255)),ISNUMBER(SEARCH("ZOLO",C255))),"PG Rent & Covered Meals",IF(OR(ISNUMBER(SEARCH("GROWW",C255)),ISNUMBER(SEARCH("ZERODHA",C255)),ISNUMBER(SEARCH("MUTUAL",C255)),ISNUMBER(SEARCH("SIP",C255)),ISNUMBER(SEARCH("NIPPON",C255))),"Monthly SIP Investment",IF(OR(ISNUMBER(SEARCH("BMTC",C255)),ISNUMBER(SEARCH("BUS",C255)),ISNUMBER(SEARCH("METRO",C255)),ISNUMBER(SEARCH("CHALO",C255))),"BMTC Bus Commute",IF(OR(ISNUMBER(SEARCH("SWIGGY",C255)),ISNUMBER(SEARCH("ZOMATO",C255)),ISNUMBER(SEARCH("CANTEEN",C255)),ISNUMBER(SEARCH("LUNCH",C255)),ISNUMBER(SEARCH("FOOD",C255)),ISNUMBER(SEARCH("SUBWAY",C255))),"Daily Office Lunch (Mon–Sat)",IF(OR(ISNUMBER(SEARCH("BLINKIT",C255)),ISNUMBER(SEARCH("ZEPTO",C255)),ISNUMBER(SEARCH("RECHARGE",C255)),ISNUMBER(SEARCH("JIO",C255)),ISNUMBER(SEARCH("AIRTEL",C255)),ISNUMBER(SEARCH("PHARMACY",C255)),ISNUMBER(SEARCH("APOLLO",C255)),ISNUMBER(SEARCH("ESSENTIALS",C255)),ISNUMBER(SEARCH("LIFESTYLE",C255))),"Lifestyle & Personal Essentials",IF(OR(ISNUMBER(SEARCH("EMERGENCY",C255)),ISNUMBER(SEARCH("SWEEP",C255)),ISNUMBER(SEARCH("RESERVE",C255))),"Emergency Fund Allocation","Unallocated Flex Buffer"))))))))) | K255: =IF(C255="","",IF(J255<>"",J255,I255)) | L255: =IF(A255="","",IF(ISNUMBER(A255),TEXT(A255,"mmm-yyyy"),"Oct-2026")) | M255: =IF(D255>=5000,"🚨 High Value Debit (₹"&TEXT(D255,"#,##0")&")",IF(D255>=1000,"⚡ Notable Expense","—"))
C257: Total Statement Debits & Credits: | D257: =SUM(D6:D256) | E257: =SUM(E6:E256)

Sheet Budget vs Actual
A1: 📈 Live Budget vs Actual & Over-Budget Leakage Tracker
A3: Real-time comparison between your planned budget model and ingested bank statement entries. Automatically highlights overgrown spending.
A5: 1. INCOME SOURCES REALIZATION
A6: Category / Source | B6: Type | C6: Planned Target (₹) | D6: Actual Received (₹) | E6: Realization % | F6: Shortfall / Surplus (₹) | G6: Status Alert | H6: Progress
